<?xml version="1.0"?>
<!-- =================================================================================== -->
<!-- |    This document was autogenerated by xacro from /home/admin/ws/install/mobile_manipulator_description/share/mobile_manipulator_description/urdf/mobile_manipulator.xacro | -->
<!-- |    EDITING THIS FILE BY HAND IS NOT RECOMMENDED                                 | -->
<!-- =================================================================================== -->
<robot name="robot">
  <link name="base_link">
    <visual>
      <origin rpy="1.57 0 0" xyz="0 0 0"/>
      <geometry>
        <mesh
          filename="file:///home/jack/Documents/works/graduate/docker/packages/base/ugv_gazebo_sim/tracer/tracer_description/meshes/tracer_base_link_no_wheel.dae"/>
      </geometry>
    </visual>
    <collision>
      <origin rpy="1.57 0 0" xyz="0 0 0"/>
      <geometry>
        <mesh
          filename="file:///home/jack/Documents/works/graduate/docker/packages/base/ugv_gazebo_sim/tracer/tracer_description/meshes/tracer_base_link_no_wheel.dae"/>
      </geometry>
    </collision>
  </link>
  <link name="inertial_link">
    <inertial>
      <origin xyz="0.015 0.0231316650320557 0"/>
      <mass value="132.3898489950015"/>
      <inertia ixx="0.185196122711036" ixy="4.30144213829512E-08" ixz="5.81037523686401E-08"
        iyy="0.364893736238929" iyz="-0.000386720198091934" izz="0.223868521722778"/>
    </inertial>
  </link>
  <joint name="inertial_link_joint" type="fixed">
    <origin rpy="0 0 0" xyz="0 0 0"/>
    <parent link="base_link"/>
    <child link="inertial_link"/>
  </joint>
  <link name="wheel_left">
    <inertial>
      <origin xyz="0 0 0"/>
      <mass value="6"/>
      <inertia ixx="0.7171" ixy="0" ixz="0" iyy="0.1361" iyz="0" izz="0.7171"/>
    </inertial>
    <visual>
      <origin rpy="0 0 0" xyz="0 0 0"/>
      <geometry>
        <mesh
          filename="file:///home/jack/Documents/works/graduate/docker/packages/base/ugv_gazebo_sim/tracer/tracer_description/meshes/tracer_wheel.dae"/>
      </geometry>
    </visual>
    <collision>
      <origin rpy="0 0 0" xyz="0 0 0"/>
      <geometry>
        <mesh
          filename="file:///home/jack/Documents/works/graduate/docker/packages/base/ugv_gazebo_sim/tracer/tracer_description/meshes/tracer_wheel.dae"/>
      </geometry>
    </collision>
  </link>
  <joint name="wheel_left_joint" type="continuous">
    <origin rpy="0 0 0" xyz="0 0.17 -0.082"/>
    <parent link="base_link"/>
    <child link="wheel_left"/>
    <axis rpy="0 0 0" xyz="0 1 0"/>
  </joint>
  <link name="wheel_right">
    <inertial>
      <origin xyz="0 0 0"/>
      <mass value="6"/>
      <inertia ixx="0.7171" ixy="0" ixz="0" iyy="0.1361" iyz="0" izz="0.7171"/>
    </inertial>
    <visual>
      <origin rpy="0 0 0" xyz="0 0 0"/>
      <geometry>
        <mesh
          filename="file:///home/jack/Documents/works/graduate/docker/packages/base/ugv_gazebo_sim/tracer/tracer_description/meshes/tracer_wheel.dae"/>
      </geometry>
    </visual>
    <collision>
      <origin rpy="0 0 0" xyz="0 0 0"/>
      <geometry>
        <mesh
          filename="file:///home/jack/Documents/works/graduate/docker/packages/base/ugv_gazebo_sim/tracer/tracer_description/meshes/tracer_wheel.dae"/>
      </geometry>
    </collision>
  </link>
  <joint name="wheel_right_joint" type="continuous">
    <origin rpy="0 0 0" xyz="0 -0.17 -0.082"/>
    <parent link="base_link"/>
    <child link="wheel_right"/>
    <axis rpy="0 0 0" xyz="0 1 0"/>
  </joint>
  <link name="castor_wheel_fl_link">
    <inertial>
      <origin xyz="0 0 0"/>
      <mass value="1"/>
      <inertia ixx="0.7171" ixy="0" ixz="0" iyy="0.1361" iyz="0" izz="0.7171"/>
    </inertial>
    <visual>
      <origin rpy="0 0 0" xyz="0 0 0"/>
      <geometry>
        <mesh
          filename="file:///home/jack/Documents/works/graduate/docker/packages/base/ugv_gazebo_sim/tracer/tracer_description/meshes/castor_joint.dae"/>
      </geometry>
    </visual>
    <collision>
      <origin rpy="0 0 0" xyz="0 0 0"/>
      <geometry>
        <mesh
          filename="file:///home/jack/Documents/works/graduate/docker/packages/base/ugv_gazebo_sim/tracer/tracer_description/meshes/castor_joint.dae"/>
      </geometry>
    </collision>
  </link>
  <joint name="castor_wheel_fl_link_joint" type="continuous">
    <origin rpy="-1.5707963267948966 0 0" xyz="0.18955 0.17 -0.0380886"/>
    <parent link="base_link"/>
    <child link="castor_wheel_fl_link"/>
    <axis rpy="0 0 0" xyz="0 1 0"/>
  </joint>
  <link name="castor_wheel_fl">
    <inertial>
      <origin xyz="0 0 0"/>
      <mass value="1"/>
      <inertia ixx="0.3131" ixy="0" ixz="0" iyy="0.3131" iyz="0" izz="0.1361"/>
    </inertial>
    <visual>
      <origin rpy="0 0 0" xyz="0 0 0"/>
      <geometry>
        <mesh
          filename="file:///home/jack/Documents/works/graduate/docker/packages/base/ugv_gazebo_sim/tracer/tracer_description/meshes/castor.dae"/>
      </geometry>
    </visual>
    <collision>
      <origin rpy="0 0 0" xyz="0 0 0"/>
      <geometry>
        <mesh
          filename="file:///home/jack/Documents/works/graduate/docker/packages/base/ugv_gazebo_sim/tracer/tracer_description/meshes/castor.dae"/>
      </geometry>
    </collision>
  </link>
  <joint name="castor_wheel_fl_joint" type="continuous">
    <origin rpy="0 0 0" xyz="-0.0218084 0.067 0"/>
    <parent link="castor_wheel_fl_link"/>
    <child link="castor_wheel_fl"/>
    <axis rpy="0 0 0" xyz="0 0 1"/>
  </joint>
  <link name="castor_wheel_fr_link">
    <inertial>
      <origin xyz="0 0 0"/>
      <mass value="1"/>
      <inertia ixx="0.7171" ixy="0" ixz="0" iyy="0.1361" iyz="0" izz="0.7171"/>
    </inertial>
    <visual>
      <origin rpy="0 0 0" xyz="0 0 0"/>
      <geometry>
        <mesh
          filename="file:///home/jack/Documents/works/graduate/docker/packages/base/ugv_gazebo_sim/tracer/tracer_description/meshes/castor_joint.dae"/>
      </geometry>
    </visual>
    <collision>
      <origin rpy="0 0 0" xyz="0 0 0"/>
      <geometry>
        <mesh
          filename="file:///home/jack/Documents/works/graduate/docker/packages/base/ugv_gazebo_sim/tracer/tracer_description/meshes/castor_joint.dae"/>
      </geometry>
    </collision>
  </link>
  <joint name="castor_wheel_fr_link_joint" type="continuous">
    <origin rpy="-1.5707963267948966 0 0" xyz="0.18955 -0.17 -0.0380886"/>
    <parent link="base_link"/>
    <child link="castor_wheel_fr_link"/>
    <axis rpy="0 0 0" xyz="0 1 0"/>
  </joint>
  <link name="castor_wheel_fr">
    <inertial>
      <origin xyz="0 0 0"/>
      <mass value="1"/>
      <inertia ixx="0.3131" ixy="0" ixz="0" iyy="0.3131" iyz="0" izz="0.1361"/>
    </inertial>
    <visual>
      <origin rpy="0 0 0" xyz="0 0 0"/>
      <geometry>
        <mesh
          filename="file:///home/jack/Documents/works/graduate/docker/packages/base/ugv_gazebo_sim/tracer/tracer_description/meshes/castor.dae"/>
      </geometry>
    </visual>
    <collision>
      <origin rpy="0 0 0" xyz="0 0 0"/>
      <geometry>
        <mesh
          filename="file:///home/jack/Documents/works/graduate/docker/packages/base/ugv_gazebo_sim/tracer/tracer_description/meshes/castor.dae"/>
      </geometry>
    </collision>
  </link>
  <joint name="castor_wheel_fr_joint" type="continuous">
    <origin rpy="0 0 0" xyz="-0.0218084 0.067 0"/>
    <parent link="castor_wheel_fr_link"/>
    <child link="castor_wheel_fr"/>
    <axis rpy="0 0 0" xyz="0 0 1"/>
  </joint>
  <link name="castor_wheel_rl_link">
    <inertial>
      <origin xyz="0 0 0"/>
      <mass value="1"/>
      <inertia ixx="0.7171" ixy="0" ixz="0" iyy="0.1361" iyz="0" izz="0.7171"/>
    </inertial>
    <visual>
      <origin rpy="0 0 0" xyz="0 0 0"/>
      <geometry>
        <mesh
          filename="file:///home/jack/Documents/works/graduate/docker/packages/base/ugv_gazebo_sim/tracer/tracer_description/meshes/castor_joint.dae"/>
      </geometry>
    </visual>
    <collision>
      <origin rpy="0 0 0" xyz="0 0 0"/>
      <geometry>
        <mesh
          filename="file:///home/jack/Documents/works/graduate/docker/packages/base/ugv_gazebo_sim/tracer/tracer_description/meshes/castor_joint.dae"/>
      </geometry>
    </collision>
  </link>
  <joint name="castor_wheel_rl_link_joint" type="continuous">
    <origin rpy="-1.5707963267948966 0 0" xyz="-0.18955 0.17 -0.0380886"/>
    <parent link="base_link"/>
    <child link="castor_wheel_rl_link"/>
    <axis rpy="0 0 0" xyz="0 1 0"/>
  </joint>
  <link name="castor_wheel_rl">
    <inertial>
      <origin xyz="0 0 0"/>
      <mass value="1"/>
      <inertia ixx="0.3131" ixy="0" ixz="0" iyy="0.3131" iyz="0" izz="0.1361"/>
    </inertial>
    <visual>
      <origin rpy="0 0 0" xyz="0 0 0"/>
      <geometry>
        <mesh
          filename="file:///home/jack/Documents/works/graduate/docker/packages/base/ugv_gazebo_sim/tracer/tracer_description/meshes/castor.dae"/>
      </geometry>
    </visual>
    <collision>
      <origin rpy="0 0 0" xyz="0 0 0"/>
      <geometry>
        <mesh
          filename="file:///home/jack/Documents/works/graduate/docker/packages/base/ugv_gazebo_sim/tracer/tracer_description/meshes/castor.dae"/>
      </geometry>
    </collision>
  </link>
  <joint name="castor_wheel_rl_joint" type="continuous">
    <origin rpy="0 0 0" xyz="-0.0218084 0.067 0"/>
    <parent link="castor_wheel_rl_link"/>
    <child link="castor_wheel_rl"/>
    <axis rpy="0 0 0" xyz="0 0 1"/>
  </joint>
  <link name="castor_wheel_rr_link">
    <inertial>
      <origin xyz="0 0 0"/>
      <mass value="1"/>
      <inertia ixx="0.7171" ixy="0" ixz="0" iyy="0.1361" iyz="0" izz="0.7171"/>
    </inertial>
    <visual>
      <origin rpy="0 0 0" xyz="0 0 0"/>
      <geometry>
        <mesh
          filename="file:///home/jack/Documents/works/graduate/docker/packages/base/ugv_gazebo_sim/tracer/tracer_description/meshes/castor_joint.dae"/>
      </geometry>
    </visual>
    <collision>
      <origin rpy="0 0 0" xyz="0 0 0"/>
      <geometry>
        <mesh
          filename="file:///home/jack/Documents/works/graduate/docker/packages/base/ugv_gazebo_sim/tracer/tracer_description/meshes/castor_joint.dae"/>
      </geometry>
    </collision>
  </link>
  <joint name="castor_wheel_rr_link_joint" type="continuous">
    <origin rpy="-1.5707963267948966 0 0" xyz="-0.18955 -0.17 -0.0380886"/>
    <parent link="base_link"/>
    <child link="castor_wheel_rr_link"/>
    <axis rpy="0 0 0" xyz="0 1 0"/>
  </joint>
  <link name="castor_wheel_rr">
    <inertial>
      <origin xyz="0 0 0"/>
      <mass value="1"/>
      <inertia ixx="0.3131" ixy="0" ixz="0" iyy="0.3131" iyz="0" izz="0.1361"/>
    </inertial>
    <visual>
      <origin rpy="0 0 0" xyz="0 0 0"/>
      <geometry>
        <mesh
          filename="file:///home/jack/Documents/works/graduate/docker/packages/base/ugv_gazebo_sim/tracer/tracer_description/meshes/castor.dae"/>
      </geometry>
    </visual>
    <collision>
      <origin rpy="0 0 0" xyz="0 0 0"/>
      <geometry>
        <mesh
          filename="file:///home/jack/Documents/works/graduate/docker/packages/base/ugv_gazebo_sim/tracer/tracer_description/meshes/castor.dae"/>
      </geometry>
    </collision>
  </link>
  <joint name="castor_wheel_rr_joint" type="continuous">
    <origin rpy="0 0 0" xyz="-0.0218084 0.067 0"/>
    <parent link="castor_wheel_rr_link"/>
    <child link="castor_wheel_rr"/>
    <axis rpy="0 0 0" xyz="0 0 1"/>
  </joint>
  <link name="frame"/>
  <joint name="frame_joint" type="fixed">
    <origin rpy="0 0 0" xyz="0 0 0.016"/>
    <parent link="base_link"/>
    <child link="frame"/>
  </joint>
  <link name="lower_pillar_fl">
    <inertial>
      <origin rpy="0 0 0" xyz="0 0 0.075"/>
      <mass value="0.2595"/>
      <inertia ixx="0.0005211625" ixy="0" ixz="0" iyy="0.0005211625" iyz="0" izz="6.92e-05"/>
    </inertial>
    <visual>
      <origin rpy="0 0 0" xyz="0 0 0.075"/>
      <geometry>
        <box size="0.04 0.04 0.15"/>
      </geometry>
      <material name="Gray">
        <color rgba="0.75 0.75 0.75 1.0"/>
      </material>
    </visual>
    <collision>
      <origin rpy="0 0 0" xyz="0 0 0.075"/>
      <geometry>
        <box size="0.04 0.04 0.15"/>
      </geometry>
    </collision>
  </link>
  <joint name="lower_pillar_fl_joint" type="fixed">
    <origin rpy="0 0 0" xyz="0.155 0.115 0"/>
    <parent link="frame"/>
    <child link="lower_pillar_fl"/>
  </joint>
  <link name="lower_pillar_fr">
    <inertial>
      <origin rpy="0 0 0" xyz="0 0 0.075"/>
      <mass value="0.2595"/>
      <inertia ixx="0.0005211625" ixy="0" ixz="0" iyy="0.0005211625" iyz="0" izz="6.92e-05"/>
    </inertial>
    <visual>
      <origin rpy="0 0 0" xyz="0 0 0.075"/>
      <geometry>
        <box size="0.04 0.04 0.15"/>
      </geometry>
      <material name="Gray">
        <color rgba="0.75 0.75 0.75 1.0"/>
      </material>
    </visual>
    <collision>
      <origin rpy="0 0 0" xyz="0 0 0.075"/>
      <geometry>
        <box size="0.04 0.04 0.15"/>
      </geometry>
    </collision>
  </link>
  <joint name="lower_pillar_fr_joint" type="fixed">
    <origin rpy="0 0 0" xyz="0.155 -0.115 0"/>
    <parent link="frame"/>
    <child link="lower_pillar_fr"/>
  </joint>
  <link name="lower_pillar_rl">
    <inertial>
      <origin rpy="0 0 0" xyz="0 0 0.075"/>
      <mass value="0.2595"/>
      <inertia ixx="0.0005211625" ixy="0" ixz="0" iyy="0.0005211625" iyz="0" izz="6.92e-05"/>
    </inertial>
    <visual>
      <origin rpy="0 0 0" xyz="0 0 0.075"/>
      <geometry>
        <box size="0.04 0.04 0.15"/>
      </geometry>
      <material name="Gray">
        <color rgba="0.75 0.75 0.75 1.0"/>
      </material>
    </visual>
    <collision>
      <origin rpy="0 0 0" xyz="0 0 0.075"/>
      <geometry>
        <box size="0.04 0.04 0.15"/>
      </geometry>
    </collision>
  </link>
  <joint name="lower_pillar_rl_joint" type="fixed">
    <origin rpy="0 0 0" xyz="-0.155 0.115 0"/>
    <parent link="frame"/>
    <child link="lower_pillar_rl"/>
  </joint>
  <link name="lower_pillar_rr">
    <inertial>
      <origin rpy="0 0 0" xyz="0 0 0.075"/>
      <mass value="0.2595"/>
      <inertia ixx="0.0005211625" ixy="0" ixz="0" iyy="0.0005211625" iyz="0" izz="6.92e-05"/>
    </inertial>
    <visual>
      <origin rpy="0 0 0" xyz="0 0 0.075"/>
      <geometry>
        <box size="0.04 0.04 0.15"/>
      </geometry>
      <material name="Gray">
        <color rgba="0.75 0.75 0.75 1.0"/>
      </material>
    </visual>
    <collision>
      <origin rpy="0 0 0" xyz="0 0 0.075"/>
      <geometry>
        <box size="0.04 0.04 0.15"/>
      </geometry>
    </collision>
  </link>
  <joint name="lower_pillar_rr_joint" type="fixed">
    <origin rpy="0 0 0" xyz="-0.155 -0.115 0"/>
    <parent link="frame"/>
    <child link="lower_pillar_rr"/>
  </joint>
  <link name="lower_plate">
    <inertial>
      <origin rpy="0 0 0" xyz="0 0 0.004"/>
      <mass value="0.8920800000000001"/>
      <inertia ixx="0.005424143760000001" ixy="0" ixz="0" iyy="0.009111407759999999" iyz="0"
        izz="0.014526036"/>
    </inertial>
    <visual>
      <origin rpy="0 0 0" xyz="0 0 0.004"/>
      <geometry>
        <box size="0.35 0.27 0.008"/>
      </geometry>
      <material name="Translucent">
        <color rgba="1 1 1 0.6"/>
      </material>
    </visual>
    <collision>
      <origin rpy="0 0 0" xyz="0 0 0.004"/>
      <geometry>
        <box size="0.35 0.27 0.008"/>
      </geometry>
    </collision>
  </link>
  <joint name="lower_plate_joint" type="fixed">
    <origin rpy="0 0 0" xyz="0 0 0.15"/>
    <parent link="frame"/>
    <child link="lower_plate"/>
  </joint>
  <link name="middle_pillar_fl">
    <inertial>
      <origin rpy="0 0 0" xyz="0 0 0.15"/>
      <mass value="0.519"/>
      <inertia ixx="0.0039617" ixy="0" ixz="0" iyy="0.0039617" iyz="0" izz="0.0001384"/>
    </inertial>
    <visual>
      <origin rpy="0 0 0" xyz="0 0 0.15"/>
      <geometry>
        <box size="0.04 0.04 0.3"/>
      </geometry>
      <material name="Gray">
        <color rgba="0.75 0.75 0.75 1.0"/>
      </material>
    </visual>
    <collision>
      <origin rpy="0 0 0" xyz="0 0 0.15"/>
      <geometry>
        <box size="0.04 0.04 0.3"/>
      </geometry>
    </collision>
  </link>
  <joint name="middle_pillar_fl_joint" type="fixed">
    <origin rpy="0 0 0" xyz="0.155 0.115 0.008"/>
    <parent link="lower_plate"/>
    <child link="middle_pillar_fl"/>
  </joint>
  <link name="middle_pillar_fr">
    <inertial>
      <origin rpy="0 0 0" xyz="0 0 0.15"/>
      <mass value="0.519"/>
      <inertia ixx="0.0039617" ixy="0" ixz="0" iyy="0.0039617" iyz="0" izz="0.0001384"/>
    </inertial>
    <visual>
      <origin rpy="0 0 0" xyz="0 0 0.15"/>
      <geometry>
        <box size="0.04 0.04 0.3"/>
      </geometry>
      <material name="Gray">
        <color rgba="0.75 0.75 0.75 1.0"/>
      </material>
    </visual>
    <collision>
      <origin rpy="0 0 0" xyz="0 0 0.15"/>
      <geometry>
        <box size="0.04 0.04 0.3"/>
      </geometry>
    </collision>
  </link>
  <joint name="middle_pillar_fr_joint" type="fixed">
    <origin rpy="0 0 0" xyz="0.155 -0.115 0.008"/>
    <parent link="lower_plate"/>
    <child link="middle_pillar_fr"/>
  </joint>
  <link name="middle_pillar_rl">
    <inertial>
      <origin rpy="0 0 0" xyz="0 0 0.15"/>
      <mass value="0.519"/>
      <inertia ixx="0.0039617" ixy="0" ixz="0" iyy="0.0039617" iyz="0" izz="0.0001384"/>
    </inertial>
    <visual>
      <origin rpy="0 0 0" xyz="0 0 0.15"/>
      <geometry>
        <box size="0.04 0.04 0.3"/>
      </geometry>
      <material name="Gray">
        <color rgba="0.75 0.75 0.75 1.0"/>
      </material>
    </visual>
    <collision>
      <origin rpy="0 0 0" xyz="0 0 0.15"/>
      <geometry>
        <box size="0.04 0.04 0.3"/>
      </geometry>
    </collision>
  </link>
  <joint name="middle_pillar_rl_joint" type="fixed">
    <origin rpy="0 0 0" xyz="-0.155 0.115 0.008"/>
    <parent link="lower_plate"/>
    <child link="middle_pillar_rl"/>
  </joint>
  <link name="middle_pillar_rr">
    <inertial>
      <origin rpy="0 0 0" xyz="0 0 0.15"/>
      <mass value="0.519"/>
      <inertia ixx="0.0039617" ixy="0" ixz="0" iyy="0.0039617" iyz="0" izz="0.0001384"/>
    </inertial>
    <visual>
      <origin rpy="0 0 0" xyz="0 0 0.15"/>
      <geometry>
        <box size="0.04 0.04 0.3"/>
      </geometry>
      <material name="Gray">
        <color rgba="0.75 0.75 0.75 1.0"/>
      </material>
    </visual>
    <collision>
      <origin rpy="0 0 0" xyz="0 0 0.15"/>
      <geometry>
        <box size="0.04 0.04 0.3"/>
      </geometry>
    </collision>
  </link>
  <joint name="middle_pillar_rr_joint" type="fixed">
    <origin rpy="0 0 0" xyz="-0.155 -0.115 0.008"/>
    <parent link="lower_plate"/>
    <child link="middle_pillar_rr"/>
  </joint>
  <link name="middle_plate">
    <inertial>
      <origin rpy="0 0 0" xyz="0 0 0.004"/>
      <mass value="0.8920800000000001"/>
      <inertia ixx="0.005424143760000001" ixy="0" ixz="0" iyy="0.009111407759999999" iyz="0"
        izz="0.014526036"/>
    </inertial>
    <visual>
      <origin rpy="0 0 0" xyz="0 0 0.004"/>
      <geometry>
        <box size="0.35 0.27 0.008"/>
      </geometry>
      <material name="Translucent">
        <color rgba="1 1 1 0.6"/>
      </material>
    </visual>
    <collision>
      <origin rpy="0 0 0" xyz="0 0 0.004"/>
      <geometry>
        <box size="0.35 0.27 0.008"/>
      </geometry>
    </collision>
  </link>
  <joint name="middle_plate_joint" type="fixed">
    <origin rpy="0 0 0" xyz="0 0 0.308"/>
    <parent link="lower_plate"/>
    <child link="middle_plate"/>
  </joint>
  <link name="upper_pillar_fl">
    <inertial>
      <origin rpy="0 0 0" xyz="0 0 0.1"/>
      <mass value="0.34600000000000003"/>
      <inertia ixx="0.001199466666666667" ixy="0" ixz="0" iyy="0.001199466666666667" iyz="0"
        izz="9.226666666666668e-05"/>
    </inertial>
    <visual>
      <origin rpy="0 0 0" xyz="0 0 0.1"/>
      <geometry>
        <box size="0.04 0.04 0.2"/>
      </geometry>
      <material name="Gray">
        <color rgba="0.75 0.75 0.75 1.0"/>
      </material>
    </visual>
    <collision>
      <origin rpy="0 0 0" xyz="0 0 0.1"/>
      <geometry>
        <box size="0.04 0.04 0.2"/>
      </geometry>
    </collision>
  </link>
  <joint name="upper_pillar_fl_joint" type="fixed">
    <origin rpy="0 0 0" xyz="0.155 0.115 0.008"/>
    <parent link="middle_plate"/>
    <child link="upper_pillar_fl"/>
  </joint>
  <link name="upper_pillar_fr">
    <inertial>
      <origin rpy="0 0 0" xyz="0 0 0.1"/>
      <mass value="0.34600000000000003"/>
      <inertia ixx="0.001199466666666667" ixy="0" ixz="0" iyy="0.001199466666666667" iyz="0"
        izz="9.226666666666668e-05"/>
    </inertial>
    <visual>
      <origin rpy="0 0 0" xyz="0 0 0.1"/>
      <geometry>
        <box size="0.04 0.04 0.2"/>
      </geometry>
      <material name="Gray">
        <color rgba="0.75 0.75 0.75 1.0"/>
      </material>
    </visual>
    <collision>
      <origin rpy="0 0 0" xyz="0 0 0.1"/>
      <geometry>
        <box size="0.04 0.04 0.2"/>
      </geometry>
    </collision>
  </link>
  <joint name="upper_pillar_fr_joint" type="fixed">
    <origin rpy="0 0 0" xyz="0.155 -0.115 0.008"/>
    <parent link="middle_plate"/>
    <child link="upper_pillar_fr"/>
  </joint>
  <link name="upper_pillar_rl">
    <inertial>
      <origin rpy="0 0 0" xyz="0 0 0.1"/>
      <mass value="0.34600000000000003"/>
      <inertia ixx="0.001199466666666667" ixy="0" ixz="0" iyy="0.001199466666666667" iyz="0"
        izz="9.226666666666668e-05"/>
    </inertial>
    <visual>
      <origin rpy="0 0 0" xyz="0 0 0.1"/>
      <geometry>
        <box size="0.04 0.04 0.2"/>
      </geometry>
      <material name="Gray">
        <color rgba="0.75 0.75 0.75 1.0"/>
      </material>
    </visual>
    <collision>
      <origin rpy="0 0 0" xyz="0 0 0.1"/>
      <geometry>
        <box size="0.04 0.04 0.2"/>
      </geometry>
    </collision>
  </link>
  <joint name="upper_pillar_rl_joint" type="fixed">
    <origin rpy="0 0 0" xyz="-0.155 0.115 0.008"/>
    <parent link="middle_plate"/>
    <child link="upper_pillar_rl"/>
  </joint>
  <link name="upper_pillar_rr">
    <inertial>
      <origin rpy="0 0 0" xyz="0 0 0.1"/>
      <mass value="0.34600000000000003"/>
      <inertia ixx="0.001199466666666667" ixy="0" ixz="0" iyy="0.001199466666666667" iyz="0"
        izz="9.226666666666668e-05"/>
    </inertial>
    <visual>
      <origin rpy="0 0 0" xyz="0 0 0.1"/>
      <geometry>
        <box size="0.04 0.04 0.2"/>
      </geometry>
      <material name="Gray">
        <color rgba="0.75 0.75 0.75 1.0"/>
      </material>
    </visual>
    <collision>
      <origin rpy="0 0 0" xyz="0 0 0.1"/>
      <geometry>
        <box size="0.04 0.04 0.2"/>
      </geometry>
    </collision>
  </link>
  <joint name="upper_pillar_rr_joint" type="fixed">
    <origin rpy="0 0 0" xyz="-0.155 -0.115 0.008"/>
    <parent link="middle_plate"/>
    <child link="upper_pillar_rr"/>
  </joint>
  <link name="beam_left">
    <inertial>
      <origin rpy="0 0 0" xyz="0 0 0.3"/>
      <mass value="1.038"/>
      <inertia ixx="0.0312784" ixy="0" ixz="0" iyy="0.0312784" iyz="0" izz="0.0002768"/>
    </inertial>
    <visual>
      <origin rpy="0 0 0" xyz="0 0 0.3"/>
      <geometry>
        <box size="0.04 0.04 0.6"/>
      </geometry>
      <material name="Gray">
        <color rgba="0.75 0.75 0.75 1.0"/>
      </material>
    </visual>
    <collision>
      <origin rpy="0 0 0" xyz="0 0 0.3"/>
      <geometry>
        <box size="0.04 0.04 0.6"/>
      </geometry>
    </collision>
  </link>
  <joint name="beam_left_joint" type="fixed">
    <origin rpy="0 1.5707963267948966 0" xyz="-0.02 0 0.22"/>
    <parent link="upper_pillar_rl"/>
    <child link="beam_left"/>
  </joint>
  <link name="beam_right">
    <inertial>
      <origin rpy="0 0 0" xyz="0 0 0.3"/>
      <mass value="1.038"/>
      <inertia ixx="0.0312784" ixy="0" ixz="0" iyy="0.0312784" iyz="0" izz="0.0002768"/>
    </inertial>
    <visual>
      <origin rpy="0 0 0" xyz="0 0 0.3"/>
      <geometry>
        <box size="0.04 0.04 0.6"/>
      </geometry>
      <material name="Gray">
        <color rgba="0.75 0.75 0.75 1.0"/>
      </material>
    </visual>
    <collision>
      <origin rpy="0 0 0" xyz="0 0 0.3"/>
      <geometry>
        <box size="0.04 0.04 0.6"/>
      </geometry>
    </collision>
  </link>
  <joint name="beam_right_joint" type="fixed">
    <origin rpy="0 1.5707963267948966 0" xyz="-0.02 0 0.22"/>
    <parent link="upper_pillar_rr"/>
    <child link="beam_right"/>
  </joint>
  <link name="beam_fl">
    <inertial>
      <origin rpy="0 0 0" xyz="0 0 0.075"/>
      <mass value="0.168"/>
      <inertia ixx="0.00032060000000000004" ixy="0" ixz="0" iyy="0.0003374" iyz="0"
        izz="2.8000000000000003e-05"/>
    </inertial>
    <visual>
      <origin rpy="0 0 0" xyz="0 0 0.075"/>
      <geometry>
        <box size="0.04 0.02 0.15"/>
      </geometry>
      <material name="Gray">
        <color rgba="0.75 0.75 0.75 1.0"/>
      </material>
    </visual>
    <collision>
      <origin rpy="0 0 0" xyz="0 0 0.075"/>
      <geometry>
        <box size="0.04 0.02 0.15"/>
      </geometry>
    </collision>
  </link>
  <joint name="beam_fl_joint" type="fixed">
    <origin rpy="-1.5707963267948966 0 0" xyz="0 0.02 0.23"/>
    <parent link="upper_pillar_fl"/>
    <child link="beam_fl"/>
  </joint>
  <link name="beam_fm">
    <inertial>
      <origin rpy="0 0 0" xyz="0 0 0.095"/>
      <mass value="0.3287"/>
      <inertia ixx="0.0010326658333333332" ixy="0" ixz="0" iyy="0.0010326658333333332" iyz="0"
        izz="8.765333333333334e-05"/>
    </inertial>
    <visual>
      <origin rpy="0 0 0" xyz="0 0 0.095"/>
      <geometry>
        <box size="0.04 0.04 0.19"/>
      </geometry>
      <material name="Gray">
        <color rgba="0.75 0.75 0.75 1.0"/>
      </material>
    </visual>
    <collision>
      <origin rpy="0 0 0" xyz="0 0 0.095"/>
      <geometry>
        <box size="0.04 0.04 0.19"/>
      </geometry>
    </collision>
  </link>
  <joint name="beam_fm_joint" type="fixed">
    <origin rpy="1.5707963267948966 0 0" xyz="0 -0.02 0.22"/>
    <parent link="upper_pillar_fl"/>
    <child link="beam_fm"/>
  </joint>
  <link name="beam_fr">
    <inertial>
      <origin rpy="0 0 0" xyz="0 0 0.075"/>
      <mass value="0.168"/>
      <inertia ixx="0.00032060000000000004" ixy="0" ixz="0" iyy="0.0003374" iyz="0"
        izz="2.8000000000000003e-05"/>
    </inertial>
    <visual>
      <origin rpy="0 0 0" xyz="0 0 0.075"/>
      <geometry>
        <box size="0.04 0.02 0.15"/>
      </geometry>
      <material name="Gray">
        <color rgba="0.75 0.75 0.75 1.0"/>
      </material>
    </visual>
    <collision>
      <origin rpy="0 0 0" xyz="0 0 0.075"/>
      <geometry>
        <box size="0.04 0.02 0.15"/>
      </geometry>
    </collision>
  </link>
  <joint name="beam_fr_joint" type="fixed">
    <origin rpy="1.5707963267948966 0 0" xyz="0 -0.02 0.23"/>
    <parent link="upper_pillar_fr"/>
    <child link="beam_fr"/>
  </joint>
  <link name="beam_rl">
    <inertial>
      <origin rpy="0 0 0" xyz="0 0 0.075"/>
      <mass value="0.168"/>
      <inertia ixx="0.00032060000000000004" ixy="0" ixz="0" iyy="0.0003374" iyz="0"
        izz="2.8000000000000003e-05"/>
    </inertial>
    <visual>
      <origin rpy="0 0 0" xyz="0 0 0.075"/>
      <geometry>
        <box size="0.04 0.02 0.15"/>
      </geometry>
      <material name="Gray">
        <color rgba="0.75 0.75 0.75 1.0"/>
      </material>
    </visual>
    <collision>
      <origin rpy="0 0 0" xyz="0 0 0.075"/>
      <geometry>
        <box size="0.04 0.02 0.15"/>
      </geometry>
    </collision>
  </link>
  <joint name="beam_rl_joint" type="fixed">
    <origin rpy="-1.5707963267948966 0 0" xyz="0 0.02 0.23"/>
    <parent link="upper_pillar_rl"/>
    <child link="beam_rl"/>
  </joint>
  <link name="beam_rm">
    <inertial>
      <origin rpy="0 0 0" xyz="0 0 0.095"/>
      <mass value="0.3287"/>
      <inertia ixx="0.0010326658333333332" ixy="0" ixz="0" iyy="0.0010326658333333332" iyz="0"
        izz="8.765333333333334e-05"/>
    </inertial>
    <visual>
      <origin rpy="0 0 0" xyz="0 0 0.095"/>
      <geometry>
        <box size="0.04 0.04 0.19"/>
      </geometry>
      <material name="Gray">
        <color rgba="0.75 0.75 0.75 1.0"/>
      </material>
    </visual>
    <collision>
      <origin rpy="0 0 0" xyz="0 0 0.095"/>
      <geometry>
        <box size="0.04 0.04 0.19"/>
      </geometry>
    </collision>
  </link>
  <joint name="beam_rm_joint" type="fixed">
    <origin rpy="1.5707963267948966 0 0" xyz="0 -0.02 0.22"/>
    <parent link="upper_pillar_rl"/>
    <child link="beam_rm"/>
  </joint>
  <link name="beam_rr">
    <inertial>
      <origin rpy="0 0 0" xyz="0 0 0.075"/>
      <mass value="0.168"/>
      <inertia ixx="0.00032060000000000004" ixy="0" ixz="0" iyy="0.0003374" iyz="0"
        izz="2.8000000000000003e-05"/>
    </inertial>
    <visual>
      <origin rpy="0 0 0" xyz="0 0 0.075"/>
      <geometry>
        <box size="0.04 0.02 0.15"/>
      </geometry>
      <material name="Gray">
        <color rgba="0.75 0.75 0.75 1.0"/>
      </material>
    </visual>
    <collision>
      <origin rpy="0 0 0" xyz="0 0 0.075"/>
      <geometry>
        <box size="0.04 0.02 0.15"/>
      </geometry>
    </collision>
  </link>
  <joint name="beam_rr_joint" type="fixed">
    <origin rpy="1.5707963267948966 0 0" xyz="0 -0.02 0.23"/>
    <parent link="upper_pillar_rr"/>
    <child link="beam_rr"/>
  </joint>
  <link name="subbeam_left">
    <inertial>
      <origin rpy="0 0 0" xyz="0 0 0.135"/>
      <mass value="0.135"/>
      <inertia ixx="0.0008246250000000002" ixy="0" ixz="0" iyy="0.0008246250000000002" iyz="0"
        izz="9e-06"/>
    </inertial>
    <visual>
      <origin rpy="0 0 0" xyz="0 0 0.135"/>
      <geometry>
        <box size="0.02 0.02 0.27"/>
      </geometry>
      <material name="Gray">
        <color rgba="0.75 0.75 0.75 1.0"/>
      </material>
    </visual>
    <collision>
      <origin rpy="0 0 0" xyz="0 0 0.135"/>
      <geometry>
        <box size="0.02 0.02 0.27"/>
      </geometry>
    </collision>
  </link>
  <joint name="subbeam_left_joint" type="fixed">
    <origin rpy="1.5707963267948966 0 1.5707963267948966" xyz="0.02 0 0.14"/>
    <parent link="beam_rl"/>
    <child link="subbeam_left"/>
  </joint>
  <link name="subbeam_right">
    <inertial>
      <origin rpy="0 0 0" xyz="0 0 0.135"/>
      <mass value="0.135"/>
      <inertia ixx="0.0008246250000000002" ixy="0" ixz="0" iyy="0.0008246250000000002" iyz="0"
        izz="9e-06"/>
    </inertial>
    <visual>
      <origin rpy="0 0 0" xyz="0 0 0.135"/>
      <geometry>
        <box size="0.02 0.02 0.27"/>
      </geometry>
      <material name="Gray">
        <color rgba="0.75 0.75 0.75 1.0"/>
      </material>
    </visual>
    <collision>
      <origin rpy="0 0 0" xyz="0 0 0.135"/>
      <geometry>
        <box size="0.02 0.02 0.27"/>
      </geometry>
    </collision>
  </link>
  <joint name="subbeam_right_joint" type="fixed">
    <origin rpy="-1.5707963267948966 0 -1.5707963267948966" xyz="0.02 0 0.14"/>
    <parent link="beam_rr"/>
    <child link="subbeam_right"/>
  </joint>
  <link name="upper_plate">
    <inertial>
      <origin rpy="0 0 0" xyz="0 0 0.004"/>
      <mass value="1.4528159999999999"/>
      <inertia ixx="0.008833605551999999" ixy="0" ixz="0" iyy="0.039342741551999995" iyz="0"
        izz="0.04816085039999999"/>
    </inertial>
    <visual>
      <origin rpy="0 0 0" xyz="0 0 0.004"/>
      <geometry>
        <box size="0.57 0.27 0.008"/>
      </geometry>
      <material name="Translucent">
        <color rgba="1 1 1 0.6"/>
      </material>
    </visual>
    <collision>
      <origin rpy="0 0 0" xyz="0 0 0.004"/>
      <geometry>
        <box size="0.57 0.27 0.008"/>
      </geometry>
    </collision>
  </link>
  <joint name="upper_plate_joint" type="fixed">
    <origin rpy="0 0 0" xyz="0.14 0 0.248"/>
    <parent link="middle_plate"/>
    <child link="upper_plate"/>
  </joint>
  <link name="top_pillar_left">
    <inertial>
      <origin rpy="0 0 0" xyz="0 0 0.3"/>
      <mass value="0.54"/>
      <inertia ixx="0.0162405" ixy="0" ixz="0" iyy="0.0162405" iyz="0" izz="8.1e-05"/>
    </inertial>
    <visual>
      <origin rpy="0 0 0" xyz="0 0 0.3"/>
      <geometry>
        <box size="0.03 0.03 0.6"/>
      </geometry>
      <material name="Gray">
        <color rgba="0.75 0.75 0.75 1.0"/>
      </material>
    </visual>
    <collision>
      <origin rpy="0 0 0" xyz="0 0 0.3"/>
      <geometry>
        <box size="0.03 0.03 0.6"/>
      </geometry>
    </collision>
  </link>
  <joint name="top_pillar_left_joint" type="fixed">
    <origin rpy="0 -1.5707963267948966 0" xyz="-0.02 0 0.015"/>
    <parent link="beam_left"/>
    <child link="top_pillar_left"/>
  </joint>
  <link name="top_pillar_right">
    <inertial>
      <origin rpy="0 0 0" xyz="0 0 0.3"/>
      <mass value="0.54"/>
      <inertia ixx="0.0162405" ixy="0" ixz="0" iyy="0.0162405" iyz="0" izz="8.1e-05"/>
    </inertial>
    <visual>
      <origin rpy="0 0 0" xyz="0 0 0.3"/>
      <geometry>
        <box size="0.03 0.03 0.6"/>
      </geometry>
      <material name="Gray">
        <color rgba="0.75 0.75 0.75 1.0"/>
      </material>
    </visual>
    <collision>
      <origin rpy="0 0 0" xyz="0 0 0.3"/>
      <geometry>
        <box size="0.03 0.03 0.6"/>
      </geometry>
    </collision>
  </link>
  <joint name="top_pillar_right_joint" type="fixed">
    <origin rpy="0 -1.5707963267948966 0" xyz="-0.02 0 0.015"/>
    <parent link="beam_right"/>
    <child link="top_pillar_right"/>
  </joint>
  <link name="top_beam">
    <inertial>
      <origin rpy="0 0 0" xyz="0 0 0.13"/>
      <mass value="0.234"/>
      <inertia ixx="0.0013357500000000001" ixy="0" ixz="0" iyy="0.0013357500000000001" iyz="0"
        izz="3.51e-05"/>
    </inertial>
    <visual>
      <origin rpy="0 0 0" xyz="0 0 0.13"/>
      <geometry>
        <box size="0.03 0.03 0.26"/>
      </geometry>
      <material name="Gray">
        <color rgba="0.75 0.75 0.75 1.0"/>
      </material>
    </visual>
    <collision>
      <origin rpy="0 0 0" xyz="0 0 0.13"/>
      <geometry>
        <box size="0.03 0.03 0.26"/>
      </geometry>
    </collision>
  </link>
  <joint name="top_beam_joint" type="fixed">
    <origin rpy="1.5707963267948966 0 0" xyz="0 0.015 0.615"/>
    <parent link="top_pillar_left"/>
    <child link="top_beam"/>
  </joint>
  <link name="top_subbeam">
    <inertial>
      <origin rpy="0 0 0" xyz="0 0 0.1"/>
      <mass value="0.1"/>
      <inertia ixx="0.00033666666666666675" ixy="0" ixz="0" iyy="0.00033666666666666675" iyz="0"
        izz="6.6666666666666675e-06"/>
    </inertial>
    <visual>
      <origin rpy="0 0 0" xyz="0 0 0.1"/>
      <geometry>
        <box size="0.02 0.02 0.2"/>
      </geometry>
      <material name="Gray">
        <color rgba="0.75 0.75 0.75 1.0"/>
      </material>
    </visual>
    <collision>
      <origin rpy="0 0 0" xyz="0 0 0.1"/>
      <geometry>
        <box size="0.02 0.02 0.2"/>
      </geometry>
    </collision>
  </link>
  <joint name="top_subbeam_joint" type="fixed">
    <origin rpy="1.5707963267948966 0 0" xyz="0 -0.015 0.455"/>
    <parent link="top_pillar_left"/>
    <child link="top_subbeam"/>
  </joint>
  <link name="piper_base_link">
    <inertial>
      <origin rpy="0 0 0" xyz="-0.00473641164191482 2.56829134630247E-05 0.041451518036016"/>
      <mass value="1.02"/>
      <inertia ixx="0.00267433" ixy="-0.00000073" ixz="-0.00017389" iyy="0.00282612" iyz="0.0000004"
        izz="0.00089624"/>
    </inertial>
    <visual>
      <origin rpy="0 0 0" xyz="0 0 0"/>
      <geometry>
        <mesh
          filename="file:///home/jack/Documents/works/graduate/docker/packages/arm/piper_ros/src/piper_description/meshes/base_link.STL"/>
      </geometry>
      <material name="">
        <color rgba="0.792156862745098 0.819607843137255 0.933333333333333 1"/>
      </material>
    </visual>
    <collision>
      <origin rpy="0 0 0" xyz="0 0 0"/>
      <geometry>
        <mesh
          filename="file:///home/jack/Documents/works/graduate/docker/packages/arm/piper_ros/src/piper_description/meshes/base_link.STL"/>
      </geometry>
    </collision>
  </link>
  <link name="piper_link1">
    <inertial>
      <origin rpy="0 0 0" xyz="0.00032 -0.00041 -0.00348"/>
      <mass value="0.71"/>
      <inertia ixx="0.00050027" ixy="0.00000078" ixz="0.00000626" iyy="0.00040879" iyz="0.00000462"
        izz="0.00045802"/>
    </inertial>
    <visual>
      <origin rpy="0 0 0" xyz="0 0 0"/>
      <geometry>
        <mesh
          filename="file:///home/jack/Documents/works/graduate/docker/packages/arm/piper_ros/src/piper_description/meshes/link1.STL"/>
      </geometry>
      <material name="">
        <color rgba="0.792156862745098 0.819607843137255 0.933333333333333 1"/>
      </material>
    </visual>
    <collision>
      <origin rpy="0 0 0" xyz="0 0 0"/>
      <geometry>
        <mesh
          filename="file:///home/jack/Documents/works/graduate/docker/packages/arm/piper_ros/src/piper_description/meshes/link1.STL"/>
      </geometry>
    </collision>
  </link>
  <joint name="piper_joint1" type="revolute">
    <origin rpy="0 0 0" xyz="0 0 0.123"/>
    <parent link="piper_base_link"/>
    <child link="piper_link1"/>
    <axis xyz="0 0 1"/>
    <limit effort="100" lower="-2.618" upper="2.618" velocity="5"/>
  </joint>
  <link name="piper_link2">
    <inertial>
      <origin rpy="0 0 0" xyz="0.21852 -0.00861 0.00126"/>
      <mass value="1.16"/>
      <inertia ixx="0.00111915" ixy="0.00182916" ixz="0.00019233" iyy="0.06763251" iyz="0.00000767"
        izz="0.067559"/>
    </inertial>
    <visual>
      <origin rpy="0 0 0" xyz="0 0 0"/>
      <geometry>
        <mesh
          filename="file:///home/jack/Documents/works/graduate/docker/packages/arm/piper_ros/src/piper_description/meshes/link2.STL"/>
      </geometry>
      <material name="">
        <color rgba="0.792156862745098 0.819607843137255 0.933333333333333 1"/>
      </material>
    </visual>
    <collision>
      <origin rpy="0 0 0" xyz="0 0 0"/>
      <geometry>
        <mesh
          filename="file:///home/jack/Documents/works/graduate/docker/packages/arm/piper_ros/src/piper_description/meshes/link2.STL"/>
      </geometry>
    </collision>
  </link>
  <joint name="piper_joint2" type="revolute">
    <origin rpy="1.5708 -0.1359 -3.1416" xyz="0 0 0"/><!-- rpy="1.5708 -0.10095-0.03490659 -3.1416"
    /> -->
    <parent link="piper_link1"/>
    <child link="piper_link2"/>
    <axis xyz="0 0 1"/>
    <limit effort="100" lower="0" upper="3.14" velocity="5"/>
  </joint>
  <link name="piper_link3">
    <inertial>
      <origin rpy="0 0 0" xyz="-0.01999 -0.14808 -0.00053"/>
      <mass value="0.5"/>
      <inertia ixx="0.01347608" ixy="0.00161034" ixz="0.00000066" iyy="0.00046377" iyz="0.00000162"
        izz="0.01363321"/>
    </inertial>
    <visual>
      <origin rpy="0 0 0" xyz="0 0 0"/>
      <geometry>
        <mesh
          filename="file:///home/jack/Documents/works/graduate/docker/packages/arm/piper_ros/src/piper_description/meshes/link3.STL"/>
      </geometry>
      <material name="">
        <color rgba="0.792156862745098 0.819607843137255 0.933333333333333 1"/>
      </material>
    </visual>
    <collision>
      <origin rpy="0 0 0" xyz="0 0 0"/>
      <geometry>
        <mesh
          filename="file:///home/jack/Documents/works/graduate/docker/packages/arm/piper_ros/src/piper_description/meshes/link3.STL"/>
      </geometry>
    </collision>
  </link>
  <joint name="piper_joint3" type="revolute">
    <origin rpy="0 0 -1.7939" xyz="0.28503 0 0"/><!-- rpy="0 0 -1.759-0.03490659" /> -->
    <parent link="piper_link2"/>
    <child link="piper_link3"/>
    <axis xyz="0 0 1"/>
    <limit effort="100" lower="-2.967" upper="0" velocity="5"/>
  </joint>
  <link name="piper_link4">
    <inertial>
      <origin rpy="0 0 0" xyz="0.00013 -0.00076 -0.00394"/>
      <mass value="0.38"/>
      <inertia ixx="0.00017844" ixy="0.00000062" ixz="0.00000067" iyy="0.00018914" iyz="0.00000408"
        izz="0.00014613"/>
    </inertial>
    <visual>
      <origin rpy="0 0 0" xyz="0 0 0"/>
      <geometry>
        <mesh
          filename="file:///home/jack/Documents/works/graduate/docker/packages/arm/piper_ros/src/piper_description/meshes/link4.STL"/>
      </geometry>
      <material name="">
        <color rgba="0.792156862745098 0.819607843137255 0.933333333333333 1"/>
      </material>
    </visual>
    <collision>
      <origin rpy="0 0 0" xyz="0 0 0"/>
      <geometry>
        <mesh
          filename="file:///home/jack/Documents/works/graduate/docker/packages/arm/piper_ros/src/piper_description/meshes/link4.STL"/>
      </geometry>
    </collision>
  </link>
  <joint name="piper_joint4" type="revolute">
    <origin rpy="1.5708 0 0" xyz="-0.021984 -0.25075 0"/>
    <parent link="piper_link3"/>
    <child link="piper_link4"/>
    <axis xyz="0 0 1"/>
    <limit effort="100" lower="-1.745" upper="1.745" velocity="5"/>
  </joint>
  <link name="piper_link5">
    <inertial>
      <origin rpy="0 0 0" xyz="0.00018 -0.06104 -0.00227"/>
      <mass value="0.383"/>
      <inertia ixx="0.00172318" ixy="0.00000259" ixz="0.00000010" iyy="0.00017936" iyz="0.00000990"
        izz="0.00171172"/>
    </inertial>
    <visual>
      <origin rpy="0 0 0" xyz="0 0 0"/>
      <geometry>
        <mesh
          filename="file:///home/jack/Documents/works/graduate/docker/packages/arm/piper_ros/src/piper_description/meshes/link5.STL"/>
      </geometry>
      <material name="">
        <color rgba="0.792156862745098 0.819607843137255 0.933333333333333 1"/>
      </material>
    </visual>
    <collision>
      <origin rpy="0 0 0" xyz="0 0 0"/>
      <geometry>
        <mesh
          filename="file:///home/jack/Documents/works/graduate/docker/packages/arm/piper_ros/src/piper_description/meshes/link5.STL"/>
      </geometry>
    </collision>
  </link>
  <joint name="piper_joint5" type="revolute">
    <origin rpy="-1.5708 0 0" xyz="0 0 0"/>
    <parent link="piper_link4"/>
    <child link="piper_link5"/>
    <axis xyz="0 0 1"/>
    <limit effort="100" lower="-1.22" upper="1.22" velocity="5"/>
  </joint>
  <link name="piper_link6">
    <inertial>
      <origin rpy="0 0 0" xyz="-0.00003 0.00006 0.04618"/>
      <mass value="0.007"/>
      <inertia ixx="0.00152112" ixy="0.00000202" ixz="0.00000261" iyy="0.00138626" iyz="0.00000002"
        izz="0.00031152"/>
    </inertial>
    <visual>
      <origin rpy="0 0 0" xyz="0 0 0"/>
      <geometry>
        <mesh
          filename="file:///home/jack/Documents/works/graduate/docker/packages/arm/piper_ros/src/piper_description/meshes/link6.STL"/>
      </geometry>
      <material name="">
        <color rgba="0.898039215686275 0.917647058823529 0.929411764705882 1"/>
      </material>
    </visual>
    <collision>
      <origin rpy="0 0 0" xyz="0 0 0"/>
      <geometry>
        <mesh
          filename="file:///home/jack/Documents/works/graduate/docker/packages/arm/piper_ros/src/piper_description/meshes/link6.STL"/>
      </geometry>
    </collision>
  </link>
  <joint name="piper_joint6" type="revolute">
    <origin rpy="1.5708 0 0" xyz="8.8259E-05 -0.091 0"/>
    <parent link="piper_link5"/>
    <child link="piper_link6"/>
    <axis xyz="0 0 1"/>
    <limit effort="100" lower="-2.0944" upper="2.0944" velocity="3"/>
  </joint>
  <link name="piper_gripper_base">
    <inertial>
      <origin rpy="0 0 0" xyz="-0.000183807162235591 8.05033155577911E-05 0.0321436689908876"/>
      <mass value="0.45"/>
      <inertia ixx="0.00092934" ixy="0.00000034" ixz="-0.00000738" iyy="0.00071447" iyz="0.00000005"
        izz="0.00039442"/>
    </inertial>
    <visual>
      <origin rpy="0 0 0" xyz="0 0 0"/>
      <geometry>
        <mesh
          filename="file:///home/jack/Documents/works/graduate/docker/packages/arm/piper_ros/src/piper_description/meshes/gripper_base.STL"/>
      </geometry>
      <material name="">
        <color rgba="0.792156862745098 0.819607843137255 0.933333333333333 1"/>
      </material>
    </visual>
    <collision>
      <origin rpy="0 0 0" xyz="0 0 0"/>
      <geometry>
        <mesh
          filename="file:///home/jack/Documents/works/graduate/docker/packages/arm/piper_ros/src/piper_description/meshes/gripper_base.STL"/>
      </geometry>
    </collision>
  </link>
  <joint name="piper_joint6_to_gripper_base" type="fixed">
    <origin rpy="0 0 0" xyz="0 0 0"/>
    <parent link="piper_link6"/>
    <child link="piper_gripper_base"/>
  </joint>
  <link name="piper_link7">
    <inertial>
      <origin rpy="0 0 0" xyz="0.00065123185041968 -0.0491929869131989 0.00972258769184025"/>
      <mass value="0.025"/>
      <inertia ixx="0.00007371" ixy="-0.00000113" ixz="0.00000021" iyy="-0.00000113"
        iyz="-0.00001372" izz="0.0000747"/>
    </inertial>
    <visual>
      <origin rpy="0 0 0" xyz="0 0 0"/>
      <geometry>
        <mesh
          filename="file:///home/jack/Documents/works/graduate/docker/packages/arm/piper_ros/src/piper_description/meshes/link7.STL"/>
      </geometry>
      <material name="">
        <color rgba="0.792156862745098 0.819607843137255 0.933333333333333 1"/>
      </material>
    </visual>
    <collision>
      <origin rpy="0 0 0" xyz="0 0 0"/>
      <geometry>
        <mesh
          filename="file:///home/jack/Documents/works/graduate/docker/packages/arm/piper_ros/src/piper_description/meshes/link7.STL"/>
      </geometry>
    </collision>
  </link>
  <joint name="piper_joint7" type="prismatic">
    <origin rpy="1.5708 0 0" xyz="0 0 0.1358"/>
    <parent link="piper_gripper_base"/>
    <child link="piper_link7"/>
    <axis xyz="0 0 1"/>
    <limit effort="10" lower="0" upper="0.035" velocity="1"/>
  </joint>
  <link name="piper_link8">
    <inertial>
      <origin rpy="0 0 0" xyz="0.000651231850419722 -0.0491929869131991 0.00972258769184024"/>
      <mass value="0.025"/>
      <inertia ixx="0.00007371" ixy="-0.00000113" ixz="0.00000021" iyy="-0.00000113"
        iyz="-0.00001372" izz="0.0000747"/>
    </inertial>
    <visual>
      <origin rpy="0 0 0" xyz="0 0 0"/>
      <geometry>
        <mesh
          filename="file:///home/jack/Documents/works/graduate/docker/packages/arm/piper_ros/src/piper_description/meshes/link8.STL"/>
      </geometry>
      <material name="">
        <color rgba="0.792156862745098 0.819607843137255 0.933333333333333 1"/>
      </material>
    </visual>
    <collision>
      <origin rpy="0 0 0" xyz="0 0 0"/>
      <geometry>
        <mesh
          filename="file:///home/jack/Documents/works/graduate/docker/packages/arm/piper_ros/src/piper_description/meshes/link8.STL"/>
      </geometry>
    </collision>
  </link>
  <joint name="piper_joint8" type="prismatic">
    <origin rpy="1.5708 0 -3.1416" xyz="0 0 0.1358"/>
    <parent link="piper_gripper_base"/>
    <child link="piper_link8"/>
    <axis xyz="0 0 -1"/>
    <limit effort="10" lower="-0.035" upper="0" velocity="1"/>
  </joint>
  <joint name="piper_joint" type="fixed">
    <origin rpy="0 0 0" xyz="0.23 0 0.008"/>
    <parent link="upper_plate"/>
    <child link="piper_base_link"/>
  </joint>
  <link name="lidar_front_base">
    <inertial>
      <mass value="0.115"/>
      <origin rpy="0 0 0" xyz="0 0 0.02065"/>
      <inertia ixx="3.5781195833333336e-05" ixy="0" ixz="0" iyy="3.5781195833333336e-05" iyz="0"
        izz="3.887e-05"/>
    </inertial>
    <visual>
      <origin rpy="0 0 0" xyz="0 0 0.02065"/>
      <geometry>
        <cylinder length="0.0413" radius="0.026"/>
      </geometry>
      <material name="DarkGrey">
        <color rgba="0.2 0.2 0.2 1.0"/>
      </material>
    </visual>
    <collision>
      <origin rpy="0 0 0" xyz="0 0 0.02065"/>
      <geometry>
        <cylinder length="0.0413" radius="0.026"/>
      </geometry>
    </collision>
  </link>
  <joint name="lidar_front_base_joint" type="fixed">
    <origin rpy="3.141592653589793 0 0" xyz="0.144 0 0"/>
    <parent link="lower_plate"/>
    <child link="lidar_front_base"/>
  </joint>
  <link name="lidar_front"/>
  <joint name="lidar_front_laser_joint" type="fixed">
    <origin rpy="0 0 0" xyz="0 0 0.03055"/>
    <parent link="lidar_front_base"/>
    <child link="lidar_front"/>
  </joint>
  <link name="lidar_rear_base">
    <inertial>
      <mass value="0.115"/>
      <origin rpy="0 0 0" xyz="0 0 0.02065"/>
      <inertia ixx="3.5781195833333336e-05" ixy="0" ixz="0" iyy="3.5781195833333336e-05" iyz="0"
        izz="3.887e-05"/>
    </inertial>
    <visual>
      <origin rpy="0 0 0" xyz="0 0 0.02065"/>
      <geometry>
        <cylinder length="0.0413" radius="0.026"/>
      </geometry>
      <material name="DarkGrey">
        <color rgba="0.2 0.2 0.2 1.0"/>
      </material>
    </visual>
    <collision>
      <origin rpy="0 0 0" xyz="0 0 0.02065"/>
      <geometry>
        <cylinder length="0.0413" radius="0.026"/>
      </geometry>
    </collision>
  </link>
  <joint name="lidar_rear_base_joint" type="fixed">
    <origin rpy="3.141592653589793 0 0" xyz="-0.144 0 0"/>
    <parent link="lower_plate"/>
    <child link="lidar_rear_base"/>
  </joint>
  <link name="lidar_rear"/>
  <joint name="lidar_rear_laser_joint" type="fixed">
    <origin rpy="0 0 0" xyz="0 0 0.03055"/>
    <parent link="lidar_rear_base"/>
    <child link="lidar_rear"/>
  </joint><!-- camera with origin at bottom screw mount -->
  <joint name="camera_front_base_joint" type="fixed">
    <origin rpy="-1.5707963267948966 0 0" xyz="0 0.015 0.13"/>
    <parent link="top_beam"/>
    <child link="camera_front_base_link"/>
  </joint>
  <link name="camera_front_base_link">
    <visual>
      <origin rpy="0 0 0" xyz="0 0 0"/>
      <geometry>
        <mesh
          filename="file:///home/jack/Documents/works/graduate/docker/packages/sensors/OrbbecSDK_ROS2/orbbec_description/meshes/femto_bolt/femto_bolt.stl"/>
      </geometry>
      <material name="">
        <color rgba="0.792156862745098 0.819607843137255 0.933333333333333 1"/>
      </material>
    </visual>
    <collision>
      <origin rpy="0 0 0" xyz="0 0 0"/>
      <geometry>
        <mesh
          filename="file:///home/jack/Documents/works/graduate/docker/packages/sensors/OrbbecSDK_ROS2/orbbec_description/meshes/femto_bolt/femto_bolt.stl"/>
      </geometry>
    </collision>
    <inertial><!-- The following are not reliable values, and should not be used for modeling -->
      <mass value="0.2"/>
      <origin rpy="0 0 0" xyz="0 0 0"/>
      <inertia ixx="0.0001" ixy="0.0" ixz="0.0" iyy="0.0001" iyz="0.0" izz="0.0001"/>
    </inertial>
  </link><!--
  Camera Link -->
  <joint name="camera_front_link_joint" type="fixed">
    <origin rpy="0 0 0" xyz="0.03645 0.00198 0.021"/>
    <parent link="camera_front_base_link"/>
    <child link="camera_front_link"/>
  </joint>
  <link name="camera_front_link"/><!-- Depth Camera Frame -->
  <joint name="camera_front_depth_joint" type="fixed">
    <origin rpy="-0.0063718 0.1061316 0.000231" xyz="0 0 0"/>
    <parent link="camera_front_link"/>
    <child link="camera_front_depth_frame"/>
  </joint>
  <link name="camera_front_depth_frame"/>
  <joint name="camera_front_depth_optical_joint" type="fixed">
    <origin rpy="-1.5707963267948966 0 -1.5707963267948966" xyz="0 0 0"/>
    <parent link="camera_front_depth_frame"/>
    <child link="camera_front_depth_optical_frame"/>
  </joint>
  <link name="camera_front_depth_optical_frame"/><!-- IR Camera Frame -->
  <joint name="camera_front_ir_joint" type="fixed">
    <origin rpy="0 0 0" xyz="0 0.0 0"/>
    <parent link="camera_front_depth_frame"/>
    <child link="camera_front_ir_frame"/>
  </joint>
  <link name="camera_front_ir_frame"/>
  <joint name="camera_front_ir_optical_joint" type="fixed">
    <origin rpy="-1.5707963267948966 0 -1.5707963267948966" xyz="0 0 0"/>
    <parent link="camera_front_ir_frame"/>
    <child link="camera_front_ir_optical_frame"/>
  </joint>
  <link name="camera_front_ir_optical_frame"/><!-- Color Camera Frame -->
  <joint name="camera_front_color_joint" type="fixed">
    <origin rpy="0.006371800289866152 -0.10613163835054795 -0.00023102465978322808"
      xyz="-0.0021445322036743163 -0.03267627716064453 -0.0010942233800888062"/>
    <parent link="camera_front_depth_frame"/>
    <child link="camera_front_color_frame"/>
  </joint>
  <link name="camera_front_color_frame"/>
  <joint name="camera_front_color_optical_joint" type="fixed">
    <origin rpy="-1.5707963267948966 0 -1.5707963267948966" xyz="0 0 0"/>
    <parent link="camera_front_color_frame"/>
    <child link="camera_front_color_optical_frame"/>
  </joint>
  <link name="camera_front_color_optical_frame"/>
  <joint name="camera_left_joint" type="fixed">
    <origin rpy="0 0 1.5707963267948966" xyz="0 0.115 -0.031"/>
    <parent link="middle_plate"/>
    <child link="camera_left"/>
  </joint>
  <link name="camera_left">
    <inertial>
      <origin rpy="0 0 0" xyz="0.0027714370634978 -9.29434319373592E-06 0.0128014057830239"/>
      <mass value="0.0186201988654731"/>
      <inertia ixx="1.38952652762223E-05" ixy="-4.88105621547421E-09" ixz="1.98670223779875E-08"
        iyy="1.7072236178685E-06" iyz="-8.49860443053716E-09" izz="1.31795237727551E-05"/>
    </inertial>
    <visual>
      <origin rpy="0 0 0" xyz="0 0 0"/>
      <geometry>
        <mesh
          filename="file:///home/jack/Documents/works/graduate/docker/packages/sensors/OrbbecSDK_ROS2/orbbec_description/meshes/gemini2/base_link.STL"/>
      </geometry>
      <material name="">
        <color rgba="0.792156862745098 0.819607843137255 0.933333333333333 1"/>
      </material>
    </visual>
    <collision>
      <origin rpy="0 0 0" xyz="0 0 0"/>
      <geometry>
        <mesh
          filename="file:///home/jack/Documents/works/graduate/docker/packages/sensors/OrbbecSDK_ROS2/orbbec_description/meshes/gemini2/base_link.STL"/>
      </geometry>
    </collision>
  </link>
  <link name="camera_left_botter_screw_frame">
    <inertial>
      <origin rpy="0 0 0" xyz="0.00255175353418556 -0.00123907270798541 0.0118889783016768"/>
      <mass value="0.00564464822744556"/>
      <inertia ixx="3.07688942133184E-06" ixy="-1.84968755859098E-08" ixz="-9.2787127214088E-09"
        iyy="2.27625032346061E-07" iyz="1.65176768024159E-08" izz="2.93984854119768E-06"/>
    </inertial>
    <visual>
      <origin rpy="0 0 0" xyz="0 0 0"/>
      <geometry>
        <mesh
          filename="file:///home/jack/Documents/works/graduate/docker/packages/sensors/OrbbecSDK_ROS2/orbbec_description/meshes/gemini2/camera_botter_screw_frame.STL"/>
      </geometry>
      <material name="">
        <color rgba="0.792156862745098 0.819607843137255 0.933333333333333 1"/>
      </material>
    </visual>
    <collision>
      <origin rpy="0 0 0" xyz="0 0 0"/>
      <geometry>
        <mesh
          filename="file:///home/jack/Documents/works/graduate/docker/packages/sensors/OrbbecSDK_ROS2/orbbec_description/meshes/gemini2/camera_botter_screw_frame.STL"/>
      </geometry>
    </collision>
  </link>
  <joint name="camera_left_botter_screw_frame_joint" type="fixed">
    <origin rpy="0 0 0" xyz="0 0 0"/>
    <parent link="camera_left"/>
    <child link="camera_left_botter_screw_frame"/>
    <axis xyz="0 0 0"/>
  </joint>
  <link name="camera_left_infra1_frame">
    <inertial>
      <origin rpy="0 0 0" xyz="-0.000620201436687004 -1.61358465547434E-08 -1.50984520398332E-07"/>
      <mass value="0.000453168343720438"/>
      <inertia ixx="4.34107789199216E-09" ixy="-3.70099015891851E-13" ixz="-1.46784711283119E-13"
        iyy="4.84012228066652E-09" iyz="2.0076254107311E-14" izz="4.84044599033091E-09"/>
    </inertial>
    <visual>
      <origin rpy="0 0 0" xyz="0 0 0"/>
      <geometry>
        <mesh
          filename="file:///home/jack/Documents/works/graduate/docker/packages/sensors/OrbbecSDK_ROS2/orbbec_description/meshes/gemini2/camera_infra1_frame.STL"/>
      </geometry>
      <material name="">
        <color rgba="0.792156862745098 0.819607843137255 0.933333333333333 1"/>
      </material>
    </visual>
    <collision>
      <origin rpy="0 0 0" xyz="0 0 0"/>
      <geometry>
        <mesh
          filename="file:///home/jack/Documents/works/graduate/docker/packages/sensors/OrbbecSDK_ROS2/orbbec_description/meshes/gemini2/camera_infra1_frame.STL"/>
      </geometry>
    </collision>
  </link>
  <joint name="camera_left_infra1_frame_joint" type="fixed">
    <origin rpy="0 0 0" xyz="0.01491 -0.025 0.0125"/>
    <parent link="camera_left_botter_screw_frame"/>
    <child link="camera_left_infra1_frame"/>
    <axis xyz="0 0 0"/>
  </joint>
  <link name="camera_left_infra1_optical_frame">
    <inertial>
      <origin rpy="0 0 0" xyz="1.61358465547434E-08 1.50984520398324E-07 -0.000620201436687004"/>
      <mass value="0.000453168343720438"/>
      <inertia ixx="4.84012228066652E-09" ixy="2.00762541073067E-14" ixz="3.70099015891915E-13"
        iyy="4.84044599033091E-09" iyz="1.46784711283141E-13" izz="4.34107789199216E-09"/>
    </inertial>
    <visual>
      <origin rpy="0 0 0" xyz="0 0 0"/>
      <geometry>
        <mesh
          filename="file:///home/jack/Documents/works/graduate/docker/packages/sensors/OrbbecSDK_ROS2/orbbec_description/meshes/gemini2/camera_infra1_optical_frame.STL"/>
      </geometry>
      <material name="">
        <color rgba="0.792156862745098 0.819607843137255 0.933333333333333 1"/>
      </material>
    </visual>
    <collision>
      <origin rpy="0 0 0" xyz="0 0 0"/>
      <geometry>
        <mesh
          filename="file:///home/jack/Documents/works/graduate/docker/packages/sensors/OrbbecSDK_ROS2/orbbec_description/meshes/gemini2/camera_infra1_optical_frame.STL"/>
      </geometry>
    </collision>
  </link>
  <joint name="camera_left_infra1_optical_frame_joint" type="fixed">
    <origin rpy="-1.5707963267949 0 -1.5707963267949" xyz="0 0 0"/>
    <parent link="camera_left_infra1_frame"/>
    <child link="camera_left_infra1_optical_frame"/>
    <axis xyz="0 0 0"/>
  </joint>
  <link name="camera_left_color_frame">
    <inertial>
      <origin rpy="0 0 0" xyz="2.29364384785394E-07 -2.11520958501546E-07 -0.00105779474323097"/>
      <mass value="0.000139779411914196"/>
      <inertia ixx="6.11273726117097E-10" ixy="3.95051289663905E-14" ixz="1.55845266007242E-13"
        iyy="6.11076547268852E-10" iyz="2.25440284353371E-14" izz="6.69129408711142E-10"/>
    </inertial>
    <visual>
      <origin rpy="0 0 0" xyz="0 0 0"/>
      <geometry>
        <mesh
          filename="file:///home/jack/Documents/works/graduate/docker/packages/sensors/OrbbecSDK_ROS2/orbbec_description/meshes/gemini2/camera_color_frame.STL"/>
      </geometry>
      <material name="">
        <color rgba="0.792156862745098 0.819607843137255 0.933333333333333 1"/>
      </material>
    </visual>
    <collision>
      <origin rpy="0 0 0" xyz="0 0 0"/>
      <geometry>
        <mesh
          filename="file:///home/jack/Documents/works/graduate/docker/packages/sensors/OrbbecSDK_ROS2/orbbec_description/meshes/gemini2/camera_color_frame.STL"/>
      </geometry>
    </collision>
  </link>
  <joint name="camera_left_color_frame_joint" type="fixed">
    <origin rpy="-1.5707963267949 0 -1.5707963267949" xyz="0.01682 0.010995 0.012505"/>
    <parent link="camera_left_botter_screw_frame"/>
    <child link="camera_left_color_frame"/>
    <axis xyz="0 0 0"/>
  </joint>
  <link name="camera_left_color_optical_frame">
    <inertial>
      <origin rpy="0 0 0" xyz="2.29364384785394E-07 -2.11520958501541E-07 -0.00105779474323097"/>
      <mass value="0.000139779411914196"/>
      <inertia ixx="6.11273726117097E-10" ixy="3.95051289663901E-14" ixz="1.55845266007242E-13"
        iyy="6.11076547268852E-10" iyz="2.25440284353391E-14" izz="6.69129408711142E-10"/>
    </inertial>
    <visual>
      <origin rpy="0 0 0" xyz="0 0 0"/>
      <geometry>
        <mesh
          filename="file:///home/jack/Documents/works/graduate/docker/packages/sensors/OrbbecSDK_ROS2/orbbec_description/meshes/gemini2/camera_color_optical_frame.STL"/>
      </geometry>
      <material name="">
        <color rgba="0.792156862745098 0.819607843137255 0.933333333333333 1"/>
      </material>
    </visual>
    <collision>
      <origin rpy="0 0 0" xyz="0 0 0"/>
      <geometry>
        <mesh
          filename="file:///home/jack/Documents/works/graduate/docker/packages/sensors/OrbbecSDK_ROS2/orbbec_description/meshes/gemini2/camera_color_optical_frame.STL"/>
      </geometry>
    </collision>
  </link>
  <joint name="camera_left_color_optical_frame_joint" type="fixed">
    <origin rpy="0 0 0" xyz="0 0 0"/>
    <parent link="camera_left_color_frame"/>
    <child link="camera_left_color_optical_frame"/>
    <axis xyz="0 0 0"/>
  </joint>
  <link name="camera_left_infra2_frame">
    <inertial>
      <origin rpy="0 0 0" xyz="-0.000620201436687001 -1.6135846551274E-08 -1.50984520410662E-07"/>
      <mass value="0.000453168343720439"/>
      <inertia ixx="4.34107789199216E-09" ixy="-3.70099015888916E-13" ixz="-1.46784711288897E-13"
        iyy="4.84012228066651E-09" iyz="2.0076254105875E-14" izz="4.8404459903309E-09"/>
    </inertial>
    <visual>
      <origin rpy="0 0 0" xyz="0 0 0"/>
      <geometry>
        <mesh
          filename="file:///home/jack/Documents/works/graduate/docker/packages/sensors/OrbbecSDK_ROS2/orbbec_description/meshes/gemini2/camera_infra2_frame.STL"/>
      </geometry>
      <material name="">
        <color rgba="0.792156862745098 0.819607843137255 0.933333333333333 1"/>
      </material>
    </visual>
    <collision>
      <origin rpy="0 0 0" xyz="0 0 0"/>
      <geometry>
        <mesh
          filename="file:///home/jack/Documents/works/graduate/docker/packages/sensors/OrbbecSDK_ROS2/orbbec_description/meshes/gemini2/camera_infra2_frame.STL"/>
      </geometry>
    </collision>
  </link>
  <joint name="camera_left_infra2_frame_joint" type="fixed">
    <origin rpy="0 0 0" xyz="0.01491 0.025 0.0125"/>
    <parent link="camera_left_botter_screw_frame"/>
    <child link="camera_left_infra2_frame"/>
    <axis xyz="0 0 0"/>
  </joint>
  <link name="camera_left_infra2_optical_frame">
    <inertial>
      <origin rpy="0 0 0" xyz="1.6135846551274E-08 1.50984520410652E-07 -0.000620201436687001"/>
      <mass value="0.000453168343720439"/>
      <inertia ixx="4.84012228066652E-09" ixy="2.00762541058687E-14" ixz="3.70099015888909E-13"
        iyy="4.8404459903309E-09" iyz="1.46784711288896E-13" izz="4.34107789199216E-09"/>
    </inertial>
    <visual>
      <origin rpy="0 0 0" xyz="0 0 0"/>
      <geometry>
        <mesh
          filename="file:///home/jack/Documents/works/graduate/docker/packages/sensors/OrbbecSDK_ROS2/orbbec_description/meshes/gemini2/camera_infra2_optical_frame.STL"/>
      </geometry>
      <material name="">
        <color rgba="0.792156862745098 0.819607843137255 0.933333333333333 1"/>
      </material>
    </visual>
    <collision>
      <origin rpy="0 0 0" xyz="0 0 0"/>
      <geometry>
        <mesh
          filename="file:///home/jack/Documents/works/graduate/docker/packages/sensors/OrbbecSDK_ROS2/orbbec_description/meshes/gemini2/camera_infra2_optical_frame.STL"/>
      </geometry>
    </collision>
  </link>
  <joint name="camera_left_infra2_optical_frame_joint" type="fixed">
    <origin rpy="-1.5707963267949 0 -1.5707963267949" xyz="0 0 0"/>
    <parent link="camera_left_infra2_frame"/>
    <child link="camera_left_infra2_optical_frame"/>
    <axis xyz="0 0 0"/>
  </joint>
  <link name="camera_left_depth_frame">
    <inertial>
      <origin rpy="0 0 0" xyz="-0.000620201436687001 -1.6135846551274E-08 -1.50984520410661E-07"/>
      <mass value="0.000453168343720439"/>
      <inertia ixx="4.34107789199216E-09" ixy="-3.70099015888929E-13" ixz="-1.46784711288886E-13"
        iyy="4.84012228066651E-09" iyz="2.00762541058859E-14" izz="4.8404459903309E-09"/>
    </inertial>
    <visual>
      <origin rpy="0 0 0" xyz="0 0 0"/>
      <geometry>
        <mesh
          filename="file:///home/jack/Documents/works/graduate/docker/packages/sensors/OrbbecSDK_ROS2/orbbec_description/meshes/gemini2/camera_depth_frame.STL"/>
      </geometry>
      <material name="">
        <color rgba="0.792156862745098 0.819607843137255 0.933333333333333 1"/>
      </material>
    </visual>
    <collision>
      <origin rpy="0 0 0" xyz="0 0 0"/>
      <geometry>
        <mesh
          filename="file:///home/jack/Documents/works/graduate/docker/packages/sensors/OrbbecSDK_ROS2/orbbec_description/meshes/gemini2/camera_depth_frame.STL"/>
      </geometry>
    </collision>
  </link>
  <joint name="camera_left_depth_frame_joint" type="fixed">
    <origin rpy="0 0 0" xyz="0.01491 0.025 0.0125"/>
    <parent link="camera_left_botter_screw_frame"/>
    <child link="camera_left_depth_frame"/>
    <axis xyz="0 0 0"/>
  </joint>
  <joint name="camera_right_joint" type="fixed">
    <origin rpy="0 0 -1.5707963267948966" xyz="0 -0.115 -0.031"/>
    <parent link="middle_plate"/>
    <child link="camera_right"/>
  </joint>
  <link name="camera_right">
    <inertial>
      <origin rpy="0 0 0" xyz="0.0027714370634978 -9.29434319373592E-06 0.0128014057830239"/>
      <mass value="0.0186201988654731"/>
      <inertia ixx="1.38952652762223E-05" ixy="-4.88105621547421E-09" ixz="1.98670223779875E-08"
        iyy="1.7072236178685E-06" iyz="-8.49860443053716E-09" izz="1.31795237727551E-05"/>
    </inertial>
    <visual>
      <origin rpy="0 0 0" xyz="0 0 0"/>
      <geometry>
        <mesh
          filename="file:///home/jack/Documents/works/graduate/docker/packages/sensors/OrbbecSDK_ROS2/orbbec_description/meshes/gemini2/base_link.STL"/>
      </geometry>
      <material name="">
        <color rgba="0.792156862745098 0.819607843137255 0.933333333333333 1"/>
      </material>
    </visual>
    <collision>
      <origin rpy="0 0 0" xyz="0 0 0"/>
      <geometry>
        <mesh
          filename="file:///home/jack/Documents/works/graduate/docker/packages/sensors/OrbbecSDK_ROS2/orbbec_description/meshes/gemini2/base_link.STL"/>
      </geometry>
    </collision>
  </link>
  <link name="camera_right_botter_screw_frame">
    <inertial>
      <origin rpy="0 0 0" xyz="0.00255175353418556 -0.00123907270798541 0.0118889783016768"/>
      <mass value="0.00564464822744556"/>
      <inertia ixx="3.07688942133184E-06" ixy="-1.84968755859098E-08" ixz="-9.2787127214088E-09"
        iyy="2.27625032346061E-07" iyz="1.65176768024159E-08" izz="2.93984854119768E-06"/>
    </inertial>
    <visual>
      <origin rpy="0 0 0" xyz="0 0 0"/>
      <geometry>
        <mesh
          filename="file:///home/jack/Documents/works/graduate/docker/packages/sensors/OrbbecSDK_ROS2/orbbec_description/meshes/gemini2/camera_botter_screw_frame.STL"/>
      </geometry>
      <material name="">
        <color rgba="0.792156862745098 0.819607843137255 0.933333333333333 1"/>
      </material>
    </visual>
    <collision>
      <origin rpy="0 0 0" xyz="0 0 0"/>
      <geometry>
        <mesh
          filename="file:///home/jack/Documents/works/graduate/docker/packages/sensors/OrbbecSDK_ROS2/orbbec_description/meshes/gemini2/camera_botter_screw_frame.STL"/>
      </geometry>
    </collision>
  </link>
  <joint name="camera_right_botter_screw_frame_joint" type="fixed">
    <origin rpy="0 0 0" xyz="0 0 0"/>
    <parent link="camera_right"/>
    <child link="camera_right_botter_screw_frame"/>
    <axis xyz="0 0 0"/>
  </joint>
  <link name="camera_right_infra1_frame">
    <inertial>
      <origin rpy="0 0 0" xyz="-0.000620201436687004 -1.61358465547434E-08 -1.50984520398332E-07"/>
      <mass value="0.000453168343720438"/>
      <inertia ixx="4.34107789199216E-09" ixy="-3.70099015891851E-13" ixz="-1.46784711283119E-13"
        iyy="4.84012228066652E-09" iyz="2.0076254107311E-14" izz="4.84044599033091E-09"/>
    </inertial>
    <visual>
      <origin rpy="0 0 0" xyz="0 0 0"/>
      <geometry>
        <mesh
          filename="file:///home/jack/Documents/works/graduate/docker/packages/sensors/OrbbecSDK_ROS2/orbbec_description/meshes/gemini2/camera_infra1_frame.STL"/>
      </geometry>
      <material name="">
        <color rgba="0.792156862745098 0.819607843137255 0.933333333333333 1"/>
      </material>
    </visual>
    <collision>
      <origin rpy="0 0 0" xyz="0 0 0"/>
      <geometry>
        <mesh
          filename="file:///home/jack/Documents/works/graduate/docker/packages/sensors/OrbbecSDK_ROS2/orbbec_description/meshes/gemini2/camera_infra1_frame.STL"/>
      </geometry>
    </collision>
  </link>
  <joint name="camera_right_infra1_frame_joint" type="fixed">
    <origin rpy="0 0 0" xyz="0.01491 -0.025 0.0125"/>
    <parent link="camera_right_botter_screw_frame"/>
    <child link="camera_right_infra1_frame"/>
    <axis xyz="0 0 0"/>
  </joint>
  <link name="camera_right_infra1_optical_frame">
    <inertial>
      <origin rpy="0 0 0" xyz="1.61358465547434E-08 1.50984520398324E-07 -0.000620201436687004"/>
      <mass value="0.000453168343720438"/>
      <inertia ixx="4.84012228066652E-09" ixy="2.00762541073067E-14" ixz="3.70099015891915E-13"
        iyy="4.84044599033091E-09" iyz="1.46784711283141E-13" izz="4.34107789199216E-09"/>
    </inertial>
    <visual>
      <origin rpy="0 0 0" xyz="0 0 0"/>
      <geometry>
        <mesh
          filename="file:///home/jack/Documents/works/graduate/docker/packages/sensors/OrbbecSDK_ROS2/orbbec_description/meshes/gemini2/camera_infra1_optical_frame.STL"/>
      </geometry>
      <material name="">
        <color rgba="0.792156862745098 0.819607843137255 0.933333333333333 1"/>
      </material>
    </visual>
    <collision>
      <origin rpy="0 0 0" xyz="0 0 0"/>
      <geometry>
        <mesh
          filename="file:///home/jack/Documents/works/graduate/docker/packages/sensors/OrbbecSDK_ROS2/orbbec_description/meshes/gemini2/camera_infra1_optical_frame.STL"/>
      </geometry>
    </collision>
  </link>
  <joint name="camera_right_infra1_optical_frame_joint" type="fixed">
    <origin rpy="-1.5707963267949 0 -1.5707963267949" xyz="0 0 0"/>
    <parent link="camera_right_infra1_frame"/>
    <child link="camera_right_infra1_optical_frame"/>
    <axis xyz="0 0 0"/>
  </joint>
  <link name="camera_right_color_frame">
    <inertial>
      <origin rpy="0 0 0" xyz="2.29364384785394E-07 -2.11520958501546E-07 -0.00105779474323097"/>
      <mass value="0.000139779411914196"/>
      <inertia ixx="6.11273726117097E-10" ixy="3.95051289663905E-14" ixz="1.55845266007242E-13"
        iyy="6.11076547268852E-10" iyz="2.25440284353371E-14" izz="6.69129408711142E-10"/>
    </inertial>
    <visual>
      <origin rpy="0 0 0" xyz="0 0 0"/>
      <geometry>
        <mesh
          filename="file:///home/jack/Documents/works/graduate/docker/packages/sensors/OrbbecSDK_ROS2/orbbec_description/meshes/gemini2/camera_color_frame.STL"/>
      </geometry>
      <material name="">
        <color rgba="0.792156862745098 0.819607843137255 0.933333333333333 1"/>
      </material>
    </visual>
    <collision>
      <origin rpy="0 0 0" xyz="0 0 0"/>
      <geometry>
        <mesh
          filename="file:///home/jack/Documents/works/graduate/docker/packages/sensors/OrbbecSDK_ROS2/orbbec_description/meshes/gemini2/camera_color_frame.STL"/>
      </geometry>
    </collision>
  </link>
  <joint name="camera_right_color_frame_joint" type="fixed">
    <origin rpy="-1.5707963267949 0 -1.5707963267949" xyz="0.01682 0.010995 0.012505"/>
    <parent link="camera_right_botter_screw_frame"/>
    <child link="camera_right_color_frame"/>
    <axis xyz="0 0 0"/>
  </joint>
  <link name="camera_right_color_optical_frame">
    <inertial>
      <origin rpy="0 0 0" xyz="2.29364384785394E-07 -2.11520958501541E-07 -0.00105779474323097"/>
      <mass value="0.000139779411914196"/>
      <inertia ixx="6.11273726117097E-10" ixy="3.95051289663901E-14" ixz="1.55845266007242E-13"
        iyy="6.11076547268852E-10" iyz="2.25440284353391E-14" izz="6.69129408711142E-10"/>
    </inertial>
    <visual>
      <origin rpy="0 0 0" xyz="0 0 0"/>
      <geometry>
        <mesh
          filename="file:///home/jack/Documents/works/graduate/docker/packages/sensors/OrbbecSDK_ROS2/orbbec_description/meshes/gemini2/camera_color_optical_frame.STL"/>
      </geometry>
      <material name="">
        <color rgba="0.792156862745098 0.819607843137255 0.933333333333333 1"/>
      </material>
    </visual>
    <collision>
      <origin rpy="0 0 0" xyz="0 0 0"/>
      <geometry>
        <mesh
          filename="file:///home/jack/Documents/works/graduate/docker/packages/sensors/OrbbecSDK_ROS2/orbbec_description/meshes/gemini2/camera_color_optical_frame.STL"/>
      </geometry>
    </collision>
  </link>
  <joint name="camera_right_color_optical_frame_joint" type="fixed">
    <origin rpy="0 0 0" xyz="0 0 0"/>
    <parent link="camera_right_color_frame"/>
    <child link="camera_right_color_optical_frame"/>
    <axis xyz="0 0 0"/>
  </joint>
  <link name="camera_right_infra2_frame">
    <inertial>
      <origin rpy="0 0 0" xyz="-0.000620201436687001 -1.6135846551274E-08 -1.50984520410662E-07"/>
      <mass value="0.000453168343720439"/>
      <inertia ixx="4.34107789199216E-09" ixy="-3.70099015888916E-13" ixz="-1.46784711288897E-13"
        iyy="4.84012228066651E-09" iyz="2.0076254105875E-14" izz="4.8404459903309E-09"/>
    </inertial>
    <visual>
      <origin rpy="0 0 0" xyz="0 0 0"/>
      <geometry>
        <mesh
          filename="file:///home/jack/Documents/works/graduate/docker/packages/sensors/OrbbecSDK_ROS2/orbbec_description/meshes/gemini2/camera_infra2_frame.STL"/>
      </geometry>
      <material name="">
        <color rgba="0.792156862745098 0.819607843137255 0.933333333333333 1"/>
      </material>
    </visual>
    <collision>
      <origin rpy="0 0 0" xyz="0 0 0"/>
      <geometry>
        <mesh
          filename="file:///home/jack/Documents/works/graduate/docker/packages/sensors/OrbbecSDK_ROS2/orbbec_description/meshes/gemini2/camera_infra2_frame.STL"/>
      </geometry>
    </collision>
  </link>
  <joint name="camera_right_infra2_frame_joint" type="fixed">
    <origin rpy="0 0 0" xyz="0.01491 0.025 0.0125"/>
    <parent link="camera_right_botter_screw_frame"/>
    <child link="camera_right_infra2_frame"/>
    <axis xyz="0 0 0"/>
  </joint>
  <link name="camera_right_infra2_optical_frame">
    <inertial>
      <origin rpy="0 0 0" xyz="1.6135846551274E-08 1.50984520410652E-07 -0.000620201436687001"/>
      <mass value="0.000453168343720439"/>
      <inertia ixx="4.84012228066652E-09" ixy="2.00762541058687E-14" ixz="3.70099015888909E-13"
        iyy="4.8404459903309E-09" iyz="1.46784711288896E-13" izz="4.34107789199216E-09"/>
    </inertial>
    <visual>
      <origin rpy="0 0 0" xyz="0 0 0"/>
      <geometry>
        <mesh
          filename="file:///home/jack/Documents/works/graduate/docker/packages/sensors/OrbbecSDK_ROS2/orbbec_description/meshes/gemini2/camera_infra2_optical_frame.STL"/>
      </geometry>
      <material name="">
        <color rgba="0.792156862745098 0.819607843137255 0.933333333333333 1"/>
      </material>
    </visual>
    <collision>
      <origin rpy="0 0 0" xyz="0 0 0"/>
      <geometry>
        <mesh
          filename="file:///home/jack/Documents/works/graduate/docker/packages/sensors/OrbbecSDK_ROS2/orbbec_description/meshes/gemini2/camera_infra2_optical_frame.STL"/>
      </geometry>
    </collision>
  </link>
  <joint name="camera_right_infra2_optical_frame_joint" type="fixed">
    <origin rpy="-1.5707963267949 0 -1.5707963267949" xyz="0 0 0"/>
    <parent link="camera_right_infra2_frame"/>
    <child link="camera_right_infra2_optical_frame"/>
    <axis xyz="0 0 0"/>
  </joint>
  <link name="camera_right_depth_frame">
    <inertial>
      <origin rpy="0 0 0" xyz="-0.000620201436687001 -1.6135846551274E-08 -1.50984520410661E-07"/>
      <mass value="0.000453168343720439"/>
      <inertia ixx="4.34107789199216E-09" ixy="-3.70099015888929E-13" ixz="-1.46784711288886E-13"
        iyy="4.84012228066651E-09" iyz="2.00762541058859E-14" izz="4.8404459903309E-09"/>
    </inertial>
    <visual>
      <origin rpy="0 0 0" xyz="0 0 0"/>
      <geometry>
        <mesh
          filename="file:///home/jack/Documents/works/graduate/docker/packages/sensors/OrbbecSDK_ROS2/orbbec_description/meshes/gemini2/camera_depth_frame.STL"/>
      </geometry>
      <material name="">
        <color rgba="0.792156862745098 0.819607843137255 0.933333333333333 1"/>
      </material>
    </visual>
    <collision>
      <origin rpy="0 0 0" xyz="0 0 0"/>
      <geometry>
        <mesh
          filename="file:///home/jack/Documents/works/graduate/docker/packages/sensors/OrbbecSDK_ROS2/orbbec_description/meshes/gemini2/camera_depth_frame.STL"/>
      </geometry>
    </collision>
  </link>
  <joint name="camera_right_depth_frame_joint" type="fixed">
    <origin rpy="0 0 0" xyz="0.01491 0.025 0.0125"/>
    <parent link="camera_right_botter_screw_frame"/>
    <child link="camera_right_depth_frame"/>
    <axis xyz="0 0 0"/>
  </joint>
  <joint name="camera_rear_joint" type="fixed">
    <origin rpy="0 0 3.141592653589793" xyz="-0.155 0 -0.031"/>
    <parent link="middle_plate"/>
    <child link="camera_rear"/>
  </joint>
  <link name="camera_rear">
    <inertial>
      <origin rpy="0 0 0" xyz="0.0027714370634978 -9.29434319373592E-06 0.0128014057830239"/>
      <mass value="0.0186201988654731"/>
      <inertia ixx="1.38952652762223E-05" ixy="-4.88105621547421E-09" ixz="1.98670223779875E-08"
        iyy="1.7072236178685E-06" iyz="-8.49860443053716E-09" izz="1.31795237727551E-05"/>
    </inertial>
    <visual>
      <origin rpy="0 0 0" xyz="0 0 0"/>
      <geometry>
        <mesh
          filename="file:///home/jack/Documents/works/graduate/docker/packages/sensors/OrbbecSDK_ROS2/orbbec_description/meshes/gemini2/base_link.STL"/>
      </geometry>
      <material name="">
        <color rgba="0.792156862745098 0.819607843137255 0.933333333333333 1"/>
      </material>
    </visual>
    <collision>
      <origin rpy="0 0 0" xyz="0 0 0"/>
      <geometry>
        <mesh
          filename="file:///home/jack/Documents/works/graduate/docker/packages/sensors/OrbbecSDK_ROS2/orbbec_description/meshes/gemini2/base_link.STL"/>
      </geometry>
    </collision>
  </link>
  <link name="camera_rear_botter_screw_frame">
    <inertial>
      <origin rpy="0 0 0" xyz="0.00255175353418556 -0.00123907270798541 0.0118889783016768"/>
      <mass value="0.00564464822744556"/>
      <inertia ixx="3.07688942133184E-06" ixy="-1.84968755859098E-08" ixz="-9.2787127214088E-09"
        iyy="2.27625032346061E-07" iyz="1.65176768024159E-08" izz="2.93984854119768E-06"/>
    </inertial>
    <visual>
      <origin rpy="0 0 0" xyz="0 0 0"/>
      <geometry>
        <mesh
          filename="file:///home/jack/Documents/works/graduate/docker/packages/sensors/OrbbecSDK_ROS2/orbbec_description/meshes/gemini2/camera_botter_screw_frame.STL"/>
      </geometry>
      <material name="">
        <color rgba="0.792156862745098 0.819607843137255 0.933333333333333 1"/>
      </material>
    </visual>
    <collision>
      <origin rpy="0 0 0" xyz="0 0 0"/>
      <geometry>
        <mesh
          filename="file:///home/jack/Documents/works/graduate/docker/packages/sensors/OrbbecSDK_ROS2/orbbec_description/meshes/gemini2/camera_botter_screw_frame.STL"/>
      </geometry>
    </collision>
  </link>
  <joint name="camera_rear_botter_screw_frame_joint" type="fixed">
    <origin rpy="0 0 0" xyz="0 0 0"/>
    <parent link="camera_rear"/>
    <child link="camera_rear_botter_screw_frame"/>
    <axis xyz="0 0 0"/>
  </joint>
  <link name="camera_rear_infra1_frame">
    <inertial>
      <origin rpy="0 0 0" xyz="-0.000620201436687004 -1.61358465547434E-08 -1.50984520398332E-07"/>
      <mass value="0.000453168343720438"/>
      <inertia ixx="4.34107789199216E-09" ixy="-3.70099015891851E-13" ixz="-1.46784711283119E-13"
        iyy="4.84012228066652E-09" iyz="2.0076254107311E-14" izz="4.84044599033091E-09"/>
    </inertial>
    <visual>
      <origin rpy="0 0 0" xyz="0 0 0"/>
      <geometry>
        <mesh
          filename="file:///home/jack/Documents/works/graduate/docker/packages/sensors/OrbbecSDK_ROS2/orbbec_description/meshes/gemini2/camera_infra1_frame.STL"/>
      </geometry>
      <material name="">
        <color rgba="0.792156862745098 0.819607843137255 0.933333333333333 1"/>
      </material>
    </visual>
    <collision>
      <origin rpy="0 0 0" xyz="0 0 0"/>
      <geometry>
        <mesh
          filename="file:///home/jack/Documents/works/graduate/docker/packages/sensors/OrbbecSDK_ROS2/orbbec_description/meshes/gemini2/camera_infra1_frame.STL"/>
      </geometry>
    </collision>
  </link>
  <joint name="camera_rear_infra1_frame_joint" type="fixed">
    <origin rpy="0 0 0" xyz="0.01491 -0.025 0.0125"/>
    <parent link="camera_rear_botter_screw_frame"/>
    <child link="camera_rear_infra1_frame"/>
    <axis xyz="0 0 0"/>
  </joint>
  <link name="camera_rear_infra1_optical_frame">
    <inertial>
      <origin rpy="0 0 0" xyz="1.61358465547434E-08 1.50984520398324E-07 -0.000620201436687004"/>
      <mass value="0.000453168343720438"/>
      <inertia ixx="4.84012228066652E-09" ixy="2.00762541073067E-14" ixz="3.70099015891915E-13"
        iyy="4.84044599033091E-09" iyz="1.46784711283141E-13" izz="4.34107789199216E-09"/>
    </inertial>
    <visual>
      <origin rpy="0 0 0" xyz="0 0 0"/>
      <geometry>
        <mesh
          filename="file:///home/jack/Documents/works/graduate/docker/packages/sensors/OrbbecSDK_ROS2/orbbec_description/meshes/gemini2/camera_infra1_optical_frame.STL"/>
      </geometry>
      <material name="">
        <color rgba="0.792156862745098 0.819607843137255 0.933333333333333 1"/>
      </material>
    </visual>
    <collision>
      <origin rpy="0 0 0" xyz="0 0 0"/>
      <geometry>
        <mesh
          filename="file:///home/jack/Documents/works/graduate/docker/packages/sensors/OrbbecSDK_ROS2/orbbec_description/meshes/gemini2/camera_infra1_optical_frame.STL"/>
      </geometry>
    </collision>
  </link>
  <joint name="camera_rear_infra1_optical_frame_joint" type="fixed">
    <origin rpy="-1.5707963267949 0 -1.5707963267949" xyz="0 0 0"/>
    <parent link="camera_rear_infra1_frame"/>
    <child link="camera_rear_infra1_optical_frame"/>
    <axis xyz="0 0 0"/>
  </joint>
  <link name="camera_rear_color_frame">
    <inertial>
      <origin rpy="0 0 0" xyz="2.29364384785394E-07 -2.11520958501546E-07 -0.00105779474323097"/>
      <mass value="0.000139779411914196"/>
      <inertia ixx="6.11273726117097E-10" ixy="3.95051289663905E-14" ixz="1.55845266007242E-13"
        iyy="6.11076547268852E-10" iyz="2.25440284353371E-14" izz="6.69129408711142E-10"/>
    </inertial>
    <visual>
      <origin rpy="0 0 0" xyz="0 0 0"/>
      <geometry>
        <mesh
          filename="file:///home/jack/Documents/works/graduate/docker/packages/sensors/OrbbecSDK_ROS2/orbbec_description/meshes/gemini2/camera_color_frame.STL"/>
      </geometry>
      <material name="">
        <color rgba="0.792156862745098 0.819607843137255 0.933333333333333 1"/>
      </material>
    </visual>
    <collision>
      <origin rpy="0 0 0" xyz="0 0 0"/>
      <geometry>
        <mesh
          filename="file:///home/jack/Documents/works/graduate/docker/packages/sensors/OrbbecSDK_ROS2/orbbec_description/meshes/gemini2/camera_color_frame.STL"/>
      </geometry>
    </collision>
  </link>
  <joint name="camera_rear_color_frame_joint" type="fixed">
    <origin rpy="-1.5707963267949 0 -1.5707963267949" xyz="0.01682 0.010995 0.012505"/>
    <parent link="camera_rear_botter_screw_frame"/>
    <child link="camera_rear_color_frame"/>
    <axis xyz="0 0 0"/>
  </joint>
  <link name="camera_rear_color_optical_frame">
    <inertial>
      <origin rpy="0 0 0" xyz="2.29364384785394E-07 -2.11520958501541E-07 -0.00105779474323097"/>
      <mass value="0.000139779411914196"/>
      <inertia ixx="6.11273726117097E-10" ixy="3.95051289663901E-14" ixz="1.55845266007242E-13"
        iyy="6.11076547268852E-10" iyz="2.25440284353391E-14" izz="6.69129408711142E-10"/>
    </inertial>
    <visual>
      <origin rpy="0 0 0" xyz="0 0 0"/>
      <geometry>
        <mesh
          filename="file:///home/jack/Documents/works/graduate/docker/packages/sensors/OrbbecSDK_ROS2/orbbec_description/meshes/gemini2/camera_color_optical_frame.STL"/>
      </geometry>
      <material name="">
        <color rgba="0.792156862745098 0.819607843137255 0.933333333333333 1"/>
      </material>
    </visual>
    <collision>
      <origin rpy="0 0 0" xyz="0 0 0"/>
      <geometry>
        <mesh
          filename="file:///home/jack/Documents/works/graduate/docker/packages/sensors/OrbbecSDK_ROS2/orbbec_description/meshes/gemini2/camera_color_optical_frame.STL"/>
      </geometry>
    </collision>
  </link>
  <joint name="camera_rear_color_optical_frame_joint" type="fixed">
    <origin rpy="0 0 0" xyz="0 0 0"/>
    <parent link="camera_rear_color_frame"/>
    <child link="camera_rear_color_optical_frame"/>
    <axis xyz="0 0 0"/>
  </joint>
  <link name="camera_rear_infra2_frame">
    <inertial>
      <origin rpy="0 0 0" xyz="-0.000620201436687001 -1.6135846551274E-08 -1.50984520410662E-07"/>
      <mass value="0.000453168343720439"/>
      <inertia ixx="4.34107789199216E-09" ixy="-3.70099015888916E-13" ixz="-1.46784711288897E-13"
        iyy="4.84012228066651E-09" iyz="2.0076254105875E-14" izz="4.8404459903309E-09"/>
    </inertial>
    <visual>
      <origin rpy="0 0 0" xyz="0 0 0"/>
      <geometry>
        <mesh
          filename="file:///home/jack/Documents/works/graduate/docker/packages/sensors/OrbbecSDK_ROS2/orbbec_description/meshes/gemini2/camera_infra2_frame.STL"/>
      </geometry>
      <material name="">
        <color rgba="0.792156862745098 0.819607843137255 0.933333333333333 1"/>
      </material>
    </visual>
    <collision>
      <origin rpy="0 0 0" xyz="0 0 0"/>
      <geometry>
        <mesh
          filename="file:///home/jack/Documents/works/graduate/docker/packages/sensors/OrbbecSDK_ROS2/orbbec_description/meshes/gemini2/camera_infra2_frame.STL"/>
      </geometry>
    </collision>
  </link>
  <joint name="camera_rear_infra2_frame_joint" type="fixed">
    <origin rpy="0 0 0" xyz="0.01491 0.025 0.0125"/>
    <parent link="camera_rear_botter_screw_frame"/>
    <child link="camera_rear_infra2_frame"/>
    <axis xyz="0 0 0"/>
  </joint>
  <link name="camera_rear_infra2_optical_frame">
    <inertial>
      <origin rpy="0 0 0" xyz="1.6135846551274E-08 1.50984520410652E-07 -0.000620201436687001"/>
      <mass value="0.000453168343720439"/>
      <inertia ixx="4.84012228066652E-09" ixy="2.00762541058687E-14" ixz="3.70099015888909E-13"
        iyy="4.8404459903309E-09" iyz="1.46784711288896E-13" izz="4.34107789199216E-09"/>
    </inertial>
    <visual>
      <origin rpy="0 0 0" xyz="0 0 0"/>
      <geometry>
        <mesh
          filename="file:///home/jack/Documents/works/graduate/docker/packages/sensors/OrbbecSDK_ROS2/orbbec_description/meshes/gemini2/camera_infra2_optical_frame.STL"/>
      </geometry>
      <material name="">
        <color rgba="0.792156862745098 0.819607843137255 0.933333333333333 1"/>
      </material>
    </visual>
    <collision>
      <origin rpy="0 0 0" xyz="0 0 0"/>
      <geometry>
        <mesh
          filename="file:///home/jack/Documents/works/graduate/docker/packages/sensors/OrbbecSDK_ROS2/orbbec_description/meshes/gemini2/camera_infra2_optical_frame.STL"/>
      </geometry>
    </collision>
  </link>
  <joint name="camera_rear_infra2_optical_frame_joint" type="fixed">
    <origin rpy="-1.5707963267949 0 -1.5707963267949" xyz="0 0 0"/>
    <parent link="camera_rear_infra2_frame"/>
    <child link="camera_rear_infra2_optical_frame"/>
    <axis xyz="0 0 0"/>
  </joint>
  <link name="camera_rear_depth_frame">
    <inertial>
      <origin rpy="0 0 0" xyz="-0.000620201436687001 -1.6135846551274E-08 -1.50984520410661E-07"/>
      <mass value="0.000453168343720439"/>
      <inertia ixx="4.34107789199216E-09" ixy="-3.70099015888929E-13" ixz="-1.46784711288886E-13"
        iyy="4.84012228066651E-09" iyz="2.00762541058859E-14" izz="4.8404459903309E-09"/>
    </inertial>
    <visual>
      <origin rpy="0 0 0" xyz="0 0 0"/>
      <geometry>
        <mesh
          filename="file:///home/jack/Documents/works/graduate/docker/packages/sensors/OrbbecSDK_ROS2/orbbec_description/meshes/gemini2/camera_depth_frame.STL"/>
      </geometry>
      <material name="">
        <color rgba="0.792156862745098 0.819607843137255 0.933333333333333 1"/>
      </material>
    </visual>
    <collision>
      <origin rpy="0 0 0" xyz="0 0 0"/>
      <geometry>
        <mesh
          filename="file:///home/jack/Documents/works/graduate/docker/packages/sensors/OrbbecSDK_ROS2/orbbec_description/meshes/gemini2/camera_depth_frame.STL"/>
      </geometry>
    </collision>
  </link>
  <joint name="camera_rear_depth_frame_joint" type="fixed">
    <origin rpy="0 0 0" xyz="0.01491 0.025 0.0125"/>
    <parent link="camera_rear_botter_screw_frame"/>
    <child link="camera_rear_depth_frame"/>
    <axis xyz="0 0 0"/>
  </joint>
</robot>
